Workbook

Sheet factors_and_returns
A1: Date | B1: ΔL | C1: ΔS | D1: SprIG | E1: E | F1: US Treasuries, Short/Intermediate | G1: US Treasuries, Long | H1: US Taxable Munis | I1: Global ex-US Government, hedged | J1: US Public Corporates IG AAA | K1: US Public Corporates IG AA | L1: US Public Corporates IG A | M1: US Public Corporates IG BBB | N1: US Public Corporates, HY Intermediate | O1: US Public Corporates, HY Long | P1: Global ex-US Corporates, hedged | Q1: Residential Mortgage-Backed Securities (RMBS) | R1: Commercial Mortgage-Backed Securities (CMBS) | S1: Asset-Backed Securities (ABS) | T1: Corporate IG Private Placement A | U1: Corporate IG Private Placement BBB | V1: Corporate HY Private (Leveraged Loans) | W1: Residential Mortgage Whole Loans | X1: Commercial Mortgage Whole Loans | Y1: Private Equity | Z1: Real Estate (via partnerships, equity)
A2: 36556 | B2: =data!C3-data!C2 -> 0.00073 | C2: =(data!C3-data!B3)-(data!C2-data!B2) -> -0.00134 | D2: =data!D3-data!D2 -> -0.00050011 | E2: =LN(data!E3/data!E2)-LN(data!F3/data!F2) -> -0.024641961 | F2: =LN(data!G3/data!G2)-LN(data!$F3/data!$F2) -> -0.0070326348 | G2: =LN(data!H3/data!H2)-LN(data!$F3/data!$F2) -> 0.0098670047 | H2: =LN(data!I3/data!I2)-LN(data!$F3/data!$F2) -> -0.0086430609 | I2: =LN(data!J3/data!J2)-LN(data!$F3/data!$F2) -> #N/A | J2: =LN(data!K3/data!K2)-LN(data!$F3/data!$F2) -> -0.0075356714 | K2: =LN(data!L3/data!L2)-LN(data!$F3/data!$F2) -> -0.0089557551 | L2: =LN(data!M3/data!M2)-LN(data!$F3/data!$F2) -> -0.0076586994 | M2: =LN(data!N3/data!N2)-LN(data!$F3/data!$F2) -> -0.0068444803 | ... Z2: =LN(data!AA3/data!AA2)-LN(data!$F3/data!$F2) -> #N/A
A3: 36584 | B3: =data!C4-data!C3 -> -0.00256 | C3: =(data!C4-data!B4)-(data!C3-data!B3) -> -0.00186 | D3: =data!D4-data!D3 -> 0.00020339 | E3: =LN(data!E4/data!E3)-LN(data!F4/data!F3) -> 0.087977911 | F3: =LN(data!G4/data!G3)-LN(data!$F4/data!$F3) -> 0.0034173341 | G3: =LN(data!H4/data!H3)-LN(data!$F4/data!$F3) -> 0.025352296 | H3: =LN(data!I4/data!I3)-LN(data!$F4/data!$F3) -> 0.007162575 | I3: =LN(data!J4/data!J3)-LN(data!$F4/data!$F3) -> 0.0017715617 | J3: =LN(data!K4/data!K3)-LN(data!$F4/data!$F3) -> 0.0083668236 | K3: =LN(data!L4/data!L3)-LN(data!$F4/data!$F3) -> 0.0039781116 | L3: =LN(data!M4/data!M3)-LN(data!$F4/data!$F3) -> 0.0047461946 | M3: =LN(data!N4/data!N3)-LN(data!$F4/data!$F3) -> 0.0055133338 | ... Z3: =LN(data!AA4/data!AA3)-LN(data!$F4/data!$F3) -> #N/A
A4: 36616 | B4: =data!C5-data!C4 -> -0.00405 | C4: =(data!C5-data!B5)-(data!C4-data!B4) -> -0.00363 | D4: =data!D5-data!D4 -> 0.00156855 | E4: =LN(data!E5/data!E4)-LN(data!F5/data!F4) -> -0.036509749 | F4: =LN(data!G5/data!G4)-LN(data!$F5/data!$F4) -> 0.0074613851 | G4: =LN(data!H5/data!H4)-LN(data!$F5/data!$F4) -> 0.028440498 | H4: =LN(data!I5/data!I4)-LN(data!$F5/data!$F4) -> 0.016433443 | I4: =LN(data!J5/data!J4)-LN(data!$F5/data!$F4) -> 0.0067689955 | J4: =LN(data!K5/data!K4)-LN(data!$F5/data!$F4) -> 0.0091320549 | K4: =LN(data!L5/data!L4)-LN(data!$F5/data!$F4) -> 0.0058965752 | L4: =LN(data!M5/data!M4)-LN(data!$F5/data!$F4) -> 0.0036504407 | M4: =LN(data!N5/data!N4)-LN(data!$F5/data!$F4) -> 5.0021457e-05 | ... Z4: =LN(data!AA5/data!AA4)-LN(data!$F5/data!$F4) -> #N/A
A5: 36646 | B5: =data!C6-data!C5 -> 0.00208 | C5: =(data!C6-data!B6)-(data!C5-data!B5) -> 0.00011 | D5: =data!D6-data!D5 -> 0.00068669 | E5: =LN(data!E6/data!E5)-LN(data!F6/data!F5) -> -0.026792802 | F5: =LN(data!G6/data!G5)-LN(data!$F6/data!$F5) -> -0.005336898 | G5: =LN(data!H6/data!H5)-LN(data!$F6/data!$F5) -> -0.012695273 | H5: =LN(data!I6/data!I5)-LN(data!$F6/data!$F5) -> -0.010586293 | I5: =LN(data!J6/data!J5)-LN(data!$F6/data!$F5) -> 0.0011309085 | J5: =LN(data!K6/data!K5)-LN(data!$F6/data!$F5) -> -0.0058840946 | K5: =LN(data!L6/data!L5)-LN(data!$F6/data!$F5) -> -0.0091281812 | L5: =LN(data!M6/data!M5)-LN(data!$F6/data!$F5) -> -0.010607729 | M5: =LN(data!N6/data!N5)-LN(data!$F6/data!$F5) -> -0.021539083 | ... Z5: =LN(data!AA6/data!AA5)-LN(data!$F6/data!$F5) -> #N/A
A6: 36677 | B6: =data!C7-data!C6 -> 0.0006 | C6: =(data!C7-data!B7)-(data!C6-data!B6) -> 0.00064 | D6: =data!D7-data!D6 -> 0.00117919 | E6: =LN(data!E7/data!E6)-LN(data!F7/data!F6) -> 0.017575434 | F6: =LN(data!G7/data!G6)-LN(data!$F7/data!$F6) -> -0.0019040295 | G6: =LN(data!H7/data!H6)-LN(data!$F7/data!$F6) -> -0.0097048812 | H6: =LN(data!I7/data!I6)-LN(data!$F7/data!$F6) -> -0.011287557 | I6: =LN(data!J7/data!J6)-LN(data!$F7/data!$F6) -> 0.0026121039 | J6: =LN(data!K7/data!K6)-LN(data!$F7/data!$F6) -> -0.0056231076 | K6: =LN(data!L7/data!L6)-LN(data!$F7/data!$F6) -> -0.0088341114 | L6: =LN(data!M7/data!M6)-LN(data!$F7/data!$F6) -> -0.010193547 | M6: =LN(data!N7/data!N6)-LN(data!$F7/data!$F6) -> -0.010656597 | ... Z6: =LN(data!AA7/data!AA6)-LN(data!$F7/data!$F6) -> #N/A
A7: 36707 | B7: =data!C8-data!C7 -> -0.00241 | C7: =(data!C8-data!B8)-(data!C7-data!B7) -> 0.00069 | D7: =data!D8-data!D7 -> 0.00013926 | E7: =LN(data!E8/data!E7)-LN(data!F8/data!F7) -> -0.020798589 | F7: =LN(data!G8/data!G7)-LN(data!$F8/data!$F7) -> 0.010027427 | G7: =LN(data!H8/data!H7)-LN(data!$F8/data!$F7) -> 0.017120329 | H7: =LN(data!I8/data!I7)-LN(data!$F8/data!$F7) -> 0.021836852 | I7: =LN(data!J8/data!J7)-LN(data!$F8/data!$F7) -> 0.00021066213 | J7: =LN(data!K8/data!K7)-LN(data!$F8/data!$F7) -> 0.015116717 | K7: =LN(data!L8/data!L7)-LN(data!$F8/data!$F7) -> 0.016860416 | L7: =LN(data!M8/data!M7)-LN(data!$F8/data!$F7) -> 0.018452234 | M7: =LN(data!N8/data!N7)-LN(data!$F8/data!$F7) -> 0.026536989 | ... Z7: =LN(data!AA8/data!AA7)-LN(data!$F8/data!$F7) -> #N/A
A8: 36738 | B8: =data!C9-data!C8 -> 0 | C8: =(data!C9-data!B9)-(data!C8-data!B8) -> 0.00074 | D8: =data!D9-data!D8 -> -0.00022208 | E8: =LN(data!E9/data!E8)-LN(data!F9/data!F8) -> 0.054427878 | F8: =LN(data!G9/data!G8)-LN(data!$F9/data!$F8) -> 0.0021946836 | G8: =LN(data!H9/data!H8)-LN(data!$F9/data!$F8) -> 0.012533962 | H8: =LN(data!I9/data!I8)-LN(data!$F9/data!$F8) -> 0.0092920783 | I8: =LN(data!J9/data!J8)-LN(data!$F9/data!$F8) -> 0.0031939857 | J8: =LN(data!K9/data!K8)-LN(data!$F9/data!$F8) -> 0.0036195979 | K8: =LN(data!L9/data!L8)-LN(data!$F9/data!$F8) -> 0.0072179141 | L8: =LN(data!M9/data!M8)-LN(data!$F9/data!$F8) -> 0.0076787982 | M8: =LN(data!N9/data!N8)-LN(data!$F9/data!$F8) -> 0.0080092938 | ... Z8: =LN(data!AA9/data!AA8)-LN(data!$F9/data!$F8) -> #N/A
A9: 36769 | B9: =data!C10-data!C9 -> -0.00306 | C9: =(data!C10-data!B10)-(data!C9-data!B9) -> -0.00181 | D9: =data!D10-data!D9 -> -0.00015456 | E9: =LN(data!E10/data!E9)-LN(data!F10/data!F9) -> -0.06014949 | F9: =LN(data!G10/data!G9)-LN(data!$F10/data!$F9) -> 0.0051966798 | G9: =LN(data!H10/data!H9)-LN(data!$F10/data!$F9) -> 0.017376538 | H9: =LN(data!I10/data!I9)-LN(data!$F10/data!$F9) -> 0.010124662 | I9: =LN(data!J10/data!J9)-LN(data!$F10/data!$F9) -> -0.0061230993 | J9: =LN(data!K10/data!K9)-LN(data!$F10/data!$F9) -> 0.0096464726 | K9: =LN(data!L10/data!L9)-LN(data!$F10/data!$F9) -> 0.008845625 | L9: =LN(data!M10/data!M9)-LN(data!$F10/data!$F9) -> 0.0080707009 | M9: =LN(data!N10/data!N9)-LN(data!$F10/data!$F9) -> 0.0063922265 | ... Z9: =LN(data!AA10/data!AA9)-LN(data!$F10/data!$F9) -> #N/A
A10: 36799 | B10: =data!C11-data!C10 -> 0.00077 | C10: =(data!C11-data!B11)-(data!C10-data!B10) -> 0.00261 | D10: =data!D11-data!D10 -> -5.108e-05 | E10: =LN(data!E11/data!E10)-LN(data!F11/data!F10) -> -0.010201757 | F10: =LN(data!G11/data!G10)-LN(data!$F11/data!$F10) -> 0.0024374826 | G10: =LN(data!H11/data!H10)-LN(data!$F11/data!$F10) -> -0.017445065 | H10: =LN(data!I11/data!I10)-LN(data!$F11/data!$F10) -> -0.010452764 | I10: =LN(data!J11/data!J10)-LN(data!$F11/data!$F10) -> 0.0038440383 | J10: =LN(data!K11/data!K10)-LN(data!$F11/data!$F10) -> 0.001368033 | K10: =LN(data!L11/data!L10)-LN(data!$F11/data!$F10) -> 0.0028705392 | L10: =LN(data!M11/data!M10)-LN(data!$F11/data!$F10) -> 0.00057220032 | M10: =LN(data!N11/data!N10)-LN(data!$F11/data!$F10) -> -0.0027499048 | ... Z10: =LN(data!AA11/data!AA10)-LN(data!$F11/data!$F10) -> #N/A
A11: 36830 | B11: =data!C12-data!C11 -> -0.00051 | C11: =(data!C12-data!B12)-(data!C11-data!B11) -> 0.00014 | D11: =data!D12-data!D11 -> 0.00213802 | E11: =LN(data!E12/data!E11)-LN(data!F12/data!F11) -> -0.088604154 | F11: =LN(data!G12/data!G11)-LN(data!$F12/data!$F11) -> 0.0013686453 | G11: =LN(data!H12/data!H11)-LN(data!$F12/data!$F11) -> 0.010338681 | H11: =LN(data!I12/data!I11)-LN(data!$F12/data!$F11) -> 0.0056674832 | I11: =LN(data!J12/data!J11)-LN(data!$F12/data!$F11) -> 0.003051387 | J11: =LN(data!K12/data!K11)-LN(data!$F12/data!$F11) -> 0.0030979912 | K11: =LN(data!L12/data!L11)-LN(data!$F12/data!$F11) -> 0.00033029214 | L11: =LN(data!M12/data!M11)-LN(data!$F12/data!$F11) -> -0.0037822775 | M11: =LN(data!N12/data!N11)-LN(data!$F12/data!$F11) -> -0.0091723644 | ... Z11: =LN(data!AA12/data!AA11)-LN(data!$F12/data!$F11) -> #N/A
A12: 36860 | B12: =data!C13-data!C12 -> -0.00283 | C12: =(data!C13-data!B13)-(data!C12-data!B12) -> 0.00018 | D12: =data!D13-data!D12 -> 0.00167694 | E12: =LN(data!E13/data!E12)-LN(data!F13/data!F12) -> -0.0014443118 | F12: =LN(data!G13/data!G12)-LN(data!$F13/data!$F12) -> 0.0089281434 | G12: =LN(data!H13/data!H12)-LN(data!$F13/data!$F12) -> 0.025608757 | H12: =LN(data!I13/data!I12)-LN(data!$F13/data!$F12) -> 0.0020638996 | I12: =LN(data!J13/data!J12)-LN(data!$F13/data!$F12) -> 0.011205116 | J12: =LN(data!K13/data!K12)-LN(data!$F13/data!$F12) -> 0.011859787 | K12: =LN(data!L13/data!L12)-LN(data!$F13/data!$F12) -> 0.0092355464 | L12: =LN(data!M13/data!M12)-LN(data!$F13/data!$F12) -> 0.0072600435 | M12: =LN(data!N13/data!N12)-LN(data!$F13/data!$F12) -> 0.0053250553 | ... Z12: =LN(data!AA13/data!AA12)-LN(data!$F13/data!$F12) -> #N/A
A13: 36891 | B13: =data!C14-data!C13 -> -0.00356 | C13: =(data!C14-data!B14)-(data!C13-data!B13) -> 0.00161 | D13: =data!D14-data!D13 -> 0.00048089 | E13: =LN(data!E14/data!E13)-LN(data!F14/data!F13) -> 0.028535637 | F13: =LN(data!G14/data!G13)-LN(data!$F14/data!$F13) -> 0.010979045 | G13: =LN(data!H14/data!H13)-LN(data!$F14/data!$F13) -> 0.017773607 | H13: =LN(data!I14/data!I13)-LN(data!$F14/data!$F13) -> 0.018915022 | I13: =LN(data!J14/data!J13)-LN(data!$F14/data!$F13) -> 0.0040668304 | J13: =LN(data!K14/data!K13)-LN(data!$F14/data!$F13) -> 0.012719396 | K13: =LN(data!L14/data!L13)-LN(data!$F14/data!$F13) -> 0.01869618 | L13: =LN(data!M14/data!M13)-LN(data!$F14/data!$F13) -> 0.013358334 | M13: =LN(data!N14/data!N13)-LN(data!$F14/data!$F13) -> 0.010654226 | ... Z13: =LN(data!AA14/data!AA13)-LN(data!$F14/data!$F13) -> #N/A
... A307: 45838 | B307: =data!C308-data!C307 -> -0.001235 | C307: =(data!C308-data!B308)-(data!C307-data!B307) -> 0.00026 | D307: =data!D308-data!D307 -> -0.0005587 | E307: =LN(data!E308/data!E307)-LN(data!F308/data!F307) -> 0.018152184 | F307: =LN(data!G308/data!G307)-LN(data!$F308/data!$F307) -> 0.0061399269 | G307: =LN(data!H308/data!H307)-LN(data!$F308/data!$F307) -> 0.021402732 | H307: =LN(data!I308/data!I307)-LN(data!$F308/data!$F307) -> 0.0029234611 | I307: =LN(data!J308/data!J307)-LN(data!$F308/data!$F307) -> 0.0019474438 | J307: =LN(data!K308/data!K307)-LN(data!$F308/data!$F307) -> 0.0077985247 | K307: =LN(data!L308/data!L307)-LN(data!$F308/data!$F307) -> 0.011023391 | L307: =LN(data!M308/data!M307)-LN(data!$F308/data!$F307) -> 0.015044234 | M307: =LN(data!N308/data!N307)-LN(data!$F308/data!$F307) -> 0.01596715 | ... Z307: =LN(data!AA308/data!AA307)-LN(data!$F308/data!$F307) -> 0.0091102926

Sheet data
A1: Date | B1: UST 2Y YTW | C1: UST 10Y YTW | D1: IG OAS spread | E1: SP500 | F1: 1M Tbill | G1: US Treasuries, Short/Intermediate | H1: US Treasuries, Long | I1: US Taxable Munis | J1: Global ex-US Government, hedged | K1: US Public Corporates IG AAA | L1: US Public Corporates IG AA | M1: US Public Corporates IG A | N1: US Public Corporates IG BBB | O1: US Public Corporates, HY Intermediate | P1: US Public Corporates, HY Long | Q1: Global ex-US Corporates, hedged | R1: Residential Mortgage-Backed Securities (RMBS) | S1: Commercial Mortgage-Backed Securities (CMBS) | T1: Asset-Backed Securities (ABS) | U1: Corporate IG Private Placement A | V1: Corporate IG Private Placement BBB | W1: Corporate HY Private (Leveraged Loans) | X1: Residential Mortgage Whole Loans | Y1: Commercial Mortgage Whole Loans | Z1: Private Equity | AA1: Real Estate (via partnerships, equity)
A2: 36525 | B2: 0.06384 | C2: 0.06592 | D2: 0.01172013 | E2: 1394.5 | F2: 511.552 | G2: 907.67 | H2: 1001.88 | I2: 475.3216 | J2: #N/A | K2: 151.01 | L2: 154.53 | M2: 154.42 | N2: 160.43 | O2: 519.3753 | P2: 601.46 | Q2: #N/A | R2: 877.09 | S2: 100.49 | T2: 162.93 | U2: 154.26833 | V2: 159.92 | W2: #N/A | X2: #N/A | Y2: #N/A | Z2: #N/A | AA2: #N/A
A3: 36556 | B3: 0.06591 | C3: 0.06665 | D3: 0.01122002 | E3: 1366.4 | F3: 513.749 | G3: 905.18 | H3: 1016.16 | I3: 473.2549 | J3: 100.0427 | K3: 150.52 | L3: 153.81 | M3: 153.9 | N3: 160.02 | O3: 516.8433 | P3: 603.75 | Q3: #N/A | R3: 869.49 | S3: 99.57 | T3: 162.87 | U3: 154.385 | V3: 160.08667 | W3: #N/A | X3: #N/A | Y3: #N/A | Z3: #N/A | AA3: #N/A
A4: 36584 | B4: 0.06521 | C4: 0.06409 | D4: 0.01142341 | E4: 1498.6 | F4: 516.001 | G4: 912.26 | H4: 1046.82 | I4: 478.7462 | J4: 100.6594 | K4: 152.45 | L4: 155.1 | M4: 155.31 | N4: 161.61 | O4: 517.7805 | P4: 605.82 | Q4: #N/A | R4: 879.57 | S4: 100.41 | T4: 164.08 | U4: 154.79333 | V4: 160.63167 | W4: #N/A | X4: #N/A | Y4: #N/A | Z4: #N/A | AA4: #N/A
A5: 36616 | B5: 0.06479 | C5: 0.06004 | D5: 0.01299196 | E5: 1452.4 | F5: 518.689 | G5: 923.88 | H5: 1082.63 | I5: 489.2139 | J5: 101.871 | K5: 154.65 | L5: 156.83 | M5: 156.69 | N5: 162.46 | O5: 507.0651 | P5: 590.3 | Q5: #N/A | R5: 889.19 | S5: 101.86 | T5: 165.4 | U5: 155.16333 | V5: 161.03167 | W5: #N/A | X5: #N/A | Y5: #N/A | Z5: #N/A | AA5: #N/A
A6: 36646 | B6: 0.06676 | C6: 0.06212 | D6: 0.01367865 | E6: 1420.6 | F6: 521.109 | G6: 923.25 | H6: 1073.96 | I6: 486.3207 | J6: 102.4621 | K6: 154.46 | L6: 156.13 | M6: 155.76 | N6: 159.74 | O6: 508.5319 | P6: 580.6 | Q6: #N/A | R6: 889.8 | S6: 101.79 | T6: 165.5 | U6: 155.245 | V6: 160.87667 | W6: #N/A | X6: #N/A | Y6: #N/A | Z6: #N/A | AA6: #N/A
A7: 36677 | B7: 0.06672 | C7: 0.06272 | D7: 0.01485784 | E7: 1454.6 | F7: 524.285 | G7: 927.11 | H7: 1070.07 | I7: 483.7929 | J7: 103.3562 | K7: 154.53 | L7: 155.7 | M7: 155.12 | N7: 159.01 | O7: 503.0352 | P7: 580.07 | Q7: #N/A | R7: 890.21 | S7: 101.36 | T7: 165.68 | U7: 155.2 | V7: 160.545 | W7: #N/A | X7: #N/A | Y7: #N/A | Z7: #N/A | AA7: #N/A
A8: 36707 | B8: 0.06362 | C8: 0.06031 | D8: 0.0149971 | E8: 1430.8 | F8: 526.545 | G8: 940.49 | H8: 1093.24 | I8: 496.6051 | J8: 103.8236 | K8: 157.56 | L8: 159.03 | M8: 158.69 | N8: 163.99 | O8: 512.9789 | P8: 597.85 | Q8: #N/A | R8: 909.24 | S8: 104.16 | T8: 168.39 | U8: 155.91167 | V8: 161.13833 | W8: #N/A | X8: #N/A | Y8: #N/A | Z8: #N/A | AA8: #N/A
A9: 36738 | B9: 0.06288 | C9: 0.06031 | D9: 0.01477502 | E9: 1517.7 | F9: 528.938 | G9: 946.84 | H9: 1112.06 | I9: 503.5191 | J9: 104.6291 | K9: 158.85 | L9: 160.91 | M9: 160.64 | N9: 166.06 | O9: 516.4194 | P9: 609.94 | Q9: #N/A | R9: 915.08 | S9: 104.9 | T9: 169.88 | U9: 157.035 | V9: 162.145 | W9: #N/A | X9: #N/A | Y9: #N/A | Z9: #N/A | AA9: #N/A
A10: 36769 | B10: 0.06163 | C10: 0.05725 | D10: 0.01462046 | E10: 1436.5 | F10: 531.676 | G10: 956.7 | H10: 1137.41 | I10: 511.2759 | J10: 104.5287 | K10: 161.22 | L10: 163.18 | M10: 162.78 | N10: 167.99 | O10: 519.7295 | P10: 618.26 | Q10: #N/A | R10: 928.95 | S10: 106.75 | T10: 171.94 | U10: 158.28 | V10: 163.20833 | W10: #N/A | X10: #N/A | Y10: #N/A | Z10: #N/A | AA10: #N/A
A11: 36799 | B11: 0.05979 | C11: 0.05802 | D11: 0.01456938 | E11: 1429.4 | F11: 534.473 | G11: 964.08 | H11: 1123.62 | I11: 508.6212 | J11: 105.4833 | K11: 162.29 | L11: 164.51 | M11: 163.73 | N11: 168.41 | O11: 515.0157 | P11: 616.08 | Q11: #N/A | R11: 938.58 | S11: 108.18 | T11: 173.74 | U11: 159.45333 | V11: 164.2 | W11: #N/A | X11: #N/A | Y11: #N/A | Z11: #N/A | AA11: #N/A
A12: 36830 | B12: 0.05914 | C12: 0.05751 | D12: 0.0167074 | E12: 1315 | F12: 537.252 | G12: 970.42 | H12: 1141.2 | I12: 514.1716 | J12: 106.3558 | K12: 163.64 | L12: 165.42 | M12: 163.96 | N12: 167.74 | O12: 497.8189 | P12: 610.33 | Q12: #N/A | R12: 945.32 | S12: 109.12 | T12: 174.65 | U12: 160.82 | V12: 165.53333 | W12: #N/A | X12: #N/A | Y12: #N/A | Z12: #N/A | AA12: #N/A
A13: 36860 | B13: 0.05613 | C13: 0.05468 | D13: 0.01838434 | E13: 1320.3 | F13: 540.197 | G13: 984.49 | H13: 1177.22 | I13: 518.0582 | J13: 108.1438 | K13: 166.5 | L13: 167.87 | M13: 166.06 | N13: 169.56 | O13: 476.9261 | P13: 612.81 | Q13: #N/A | R13: 959.54 | S13: 111.15 | T13: 177.14 | U13: 162.64333 | V13: 167.29167 | W13: #N/A | X13: #N/A | Y13: #N/A | Z13: #N/A | AA13: #N/A
A14: 36891 | B14: 0.05096 | C14: 0.05112 | D14: 0.01886523 | E14: 1366 | F14: 543.172 | G14: 1000.84 | H14: 1204.93 | I14: 530.8581 | J14: 109.1825 | K14: 169.56 | L14: 171.98 | M14: 169.22 | N14: 172.32 | O14: 485.8125 | P14: 631.91 | Q14: #N/A | R14: 974.99 | S14: 114.03 | T14: 180.59 | U14: 164.39833 | V14: 168.68 | W14: #N/A | X14: #N/A | Y14: #N/A | Z14: #N/A | AA14: #N/A
... A99: 39478 | B99: 0.020929 | C99: 0.035931 | D99: 0.02526292 | E99: 1330.6 | F99: 674.73 | G99: 1445.27 | H99: 1978.93 | I99: 764.4776 | J99: 152.5468 | K99: 252.61 | L99: 269.04 | M99: 261.33 | N99: 272.75 | O99: 807.9279 | P99: 1455.73 | Q99: #N/A | R99: 1455.66 | S99: 174.01 | T99: 252.71 | U99: 256.67833 | V99: 269.69 | W99: #N/A | X99: #N/A | Y99: #N/A | Z99: #N/A | AA99: #N/A
A100: 39506 | B100: 0.016158 | C100: 0.035092 | D100: 0.02854885 | E100: 1322.7 | F100: 675.726 | G100: 1464.46 | H100: 1987.37 | I100: 729.4767 | J100: 153.0907 | K100: 253.03 | L100: 269.54 | M100: 261.96 | N100: 271.85 | O100: 797.6656 | P100: 1424.07 | Q100: #N/A | R100: 1455.9 | S100: 167.51 | T100: 249.23 | U100: 258.43 | V100: 270.84167 | W100: #N/A | X100: #N/A | Y100: 95.8464 | Z100: 687.97 | AA100: 1441.48
A101: 39538 | B101: 0.015824 | C101: 0.034096 | D101: 0.03386359 | E101: 1385.6 | F101: 677.281 | G101: 1473.94 | H101: 2004.63 | I101: 750.3328 | J101: 153.1783 | K101: 254.88 | L101: 267.4 | M101: 258.25 | N101: 268.82 | O101: 795.9803 | P101: 1401.88 | Q101: #N/A | R101: 1464.08 | S101: 171.95 | T101: 247.08 | U101: 259.205 | V101: 271.19333 | W101: #N/A | X101: #N/A | Y101: 97.5098 | Z101: 716.18 | AA101: 1552.82
A102: 39568 | B102: 0.022537 | C102: 0.037279 | D102: 0.02881805 | E102: 1400.4 | F102: 678.008 | G102: 1449.39 | H102: 1966.16 | I102: 759.1068 | J102: 152.1938 | K102: 253.65 | L102: 267.72 | M102: 260.61 | N102: 272.34 | O102: 830.0139 | P102: 1466.91 | Q102: #N/A | R102: 1465.48 | S102: 174.8 | T102: 244.86 | U102: 259.85667 | V102: 271.485 | W102: #N/A | X102: #N/A | Y102: 99.7839 | Z102: 748.28 | AA102: 1511.79
A103: 39599 | B103: 0.026411 | C103: 0.040595 | D103: 0.0274742 | E103: 1280 | F103: 678.193 | G103: 1435.56 | H103: 1927.01 | I103: 763.7047 | J103: 150.516 | K103: 251.91 | L103: 265.05 | M103: 257.7 | N103: 270.65 | O103: 834.2706 | P103: 1450.54 | Q103: #N/A | R103: 1457.71 | S103: 176.01 | T103: 246.28 | U103: 259.725 | V103: 271.35833 | W103: #N/A | X103: #N/A | Y103: 100.8726 | Z103: 689.66 | AA103: 1308.35
A104: 39629 | B104: 0.026164 | C104: 0.03969 | D104: 0.0306562 | E104: 1267.4 | F104: 679.391 | G104: 1443.44 | H104: 1960.05 | I104: 755.0784 | J104: 149.5365 | K104: 252.11 | L104: 262.93 | M104: 255.95 | N104: 269.17 | O104: 811.4952 | P104: 1401.86 | Q104: #N/A | R104: 1456.88 | S104: 172.26 | T104: 245.1 | U104: 259.3 | V104: 270.93 | W104: #N/A | X104: #N/A | Y104: 98.601 | Z104: 714.52 | AA104: 1328.89
A105: 39660 | B105: 0.025079 | C105: 0.039462 | D105: 0.03347127 | E105: 1282.8 | F105: 680.585 | G105: 1451.35 | H105: 1958.62 | I105: 757.9511 | J105: 151.8426 | K105: 252.34 | L105: 261.46 | M105: 253.68 | N105: 267.42 | O105: 802.2445 | P105: 1358.47 | Q105: #N/A | R105: 1454.85 | S105: 171.32 | T105: 245.16 | U105: 258.025 | V105: 270.04167 | W105: #N/A | X105: #N/A | Y105: 97.7168 | Z105: 739.5 | AA105: 1373.7
A106: 39691 | B106: 0.023669 | C106: 0.038116 | D106: 0.03482299 | E106: 1166.4 | F106: 681.636 | G106: 1465.04 | H106: 2007.25 | I106: 766.8225 | J106: 153.3891 | K106: 254.91 | L106: 262.94 | M106: 255.39 | N106: 269.5 | O106: 804.6115 | P106: 1370.51 | Q106: #N/A | R106: 1473.05 | S106: 169.92 | T106: 242.28 | U106: 256.93 | V106: 269.65 | W106: #N/A | X106: #N/A | Y106: 96.5219 | Z106: 679.58 | AA106: 1301.36
A107: 39721 | B107: 0.019599 | C107: 0.038234 | D107: 0.05145656 | E107: 968.8 | F107: 683.651 | G107: 1474.82 | H107: 2015.24 | I107: 730.8595 | J107: 153.8655 | K107: 255.35 | L107: 249.87 | M107: 230.3 | N107: 256.12 | O107: 742.4087 | P107: 1228.05 | Q107: #N/A | R107: 1484.13 | S107: 162.21 | T107: 235.97 | U107: 252.27167 | V107: 267.53333 | W107: #N/A | X107: #N/A | Y107: 92.4345 | Z107: 537.52 | AA107: 1036.07
A108: 39752 | B108: 0.01548 | C108: 0.03953 | D108: 0.06649611 | E108: 896.2 | F108: 684.432 | G108: 1484.67 | H108: 1949.44 | I108: 723.3974 | J108: 154.9711 | K108: 252.07 | L108: 243.97 | M108: 217.75 | N108: 228 | O108: 625.1731 | P108: 1018.6 | Q108: #N/A | R108: 1465.48 | S108: 146.45 | T108: 222.03 | U108: 245.12833 | V108: 260.14333 | W108: #N/A | X108: #N/A | Y108: 83.1621 | Z108: 473.14 | AA108: 879.88
A109: 39782 | B109: 0.009807 | C109: 0.0292 | D109: 0.06898989 | E109: 903.2 | F109: 685.139 | G109: 1539.56 | H109: 2189.27 | I109: 725.6991 | J109: 159.1998 | K109: 260.06 | L109: 252.01 | M109: 227.55 | N109: 234.27 | O109: 566.9635 | P109: 923.52 | Q109: #N/A | R109: 1523.05 | S109: 119.91 | T109: 221.19 | U109: 240.10333 | V109: 254.08 | W109: #N/A | X109: #N/A | Y109: 67.7804 | Z109: 499.45 | AA109: 875.2
A110: 39813 | B110: 0.007643 | C110: 0.022123 | D110: 0.0633946 | E110: 825.9 | F110: 685.172 | G110: 1569.88 | H110: 2391.27 | I110: 736.2752 | J110: 163.5356 | K110: 268.07 | L110: 266.95 | M110: 244.99 | N110: 247.54 | O110: 610.2872 | P110: 998.42 | Q110: #N/A | R110: 1548.48 | S110: 140.27 | T110: 219.89 | U110: 238.27667 | V110: 250.475 | W110: #N/A | X110: #N/A | Y110: 78.4515 | Z110: 443.53 | AA110: 825.12
A111: 39844 | B111: 0.009463 | C111: 0.028403 | D111: 0.05567222 | E111: 735.1 | F111: 685.093 | G111: 1546.81 | H111: 2184.43 | I111: 763.2312 | J111: 161.4476 | K111: 264.9 | L111: 261.59 | M111: 244.74 | N111: 252.91 | O111: 647.4725 | P111: 1048.08 | Q111: #N/A | R111: 1551.41 | S111: 135.11 | T111: 234.17 | U111: 236.78667 | V111: 248.05667 | W111: #N/A | X111: #N/A | Y111: 75.9917 | Z111: 389.02 | AA111: 691.63
... A165: 41486 | B165: 0.003089 | C165: 0.025762 | D165: 0.0160953 | E165: 1633 | F165: 689.254 | G165: 1745.97 | H165: 2772.08 | I165: 970.4765 | J165: 191.1302 | K165: 314.59 | L165: 346.18 | M165: 357.14 | N165: 412.85 | O165: 1358.33 | P165: 3005.26 | Q165: #N/A | R165: 1843.45 | S165: 250.21 | T165: 313.4 | U165: 363.57833 | V165: 422.16833 | W165: #N/A | X165: #N/A | Y165: 142.1927 | Z165: 1010.9 | AA165: 1530.45
A166: 41517 | B166: 0.003987 | C166: 0.027839 | D166: 0.01628833 | E166: 1681.5 | F166: 689.288 | G166: 1738.07 | H166: 2751.33 | I166: 956.6339 | J166: 189.9953 | K166: 313.33 | L166: 343.92 | M166: 354.55 | N166: 408.81 | O166: 1350.95 | P166: 2951.66 | Q166: 99.3793 | R166: 1838.18 | S166: 249.19 | T166: 312.75 | U166: 361.545 | V166: 419.4 | W166: #N/A | X166: #N/A | Y166: 141.5362 | Z166: 1073.79 | AA166: 1571.49
A167: 41547 | B167: 0.003168 | C167: 0.0261 | D167: 0.01608916 | E167: 1756.5 | F167: 689.32 | G167: 1750.94 | H167: 2761.52 | I167: 977.2203 | J167: 191.4491 | K167: 316.42 | L167: 346.6 | M167: 357.24 | N167: 412.75 | O167: 1364.492 | P167: 2975.51 | Q167: 100.3338 | R167: 1864.06 | S167: 251.47 | T167: 314.5 | U167: 360.03333 | V167: 417.18833 | W167: #N/A | X167: #N/A | Y167: 142.9182 | Z167: 1100.15 | AA167: 1606.34
A168: 41578 | B168: 0.00305 | C168: 0.025542 | D168: 0.01478381 | E168: 1805.8 | F168: 689.294 | G168: 1757.55 | H168: 2798.28 | I168: 984.9366 | J168: 192.9277 | K168: 318.21 | L168: 349.57 | M168: 362.1 | N168: 420.18 | O168: 1397.8825 | P168: 3083.05 | Q168: 101.5613 | R168: 1876.76 | S168: 253.27 | T168: 315.52 | U168: 358.23833 | V168: 414.69333 | W168: #N/A | X168: #N/A | Y168: 144.0635 | Z168: 1142.89 | AA168: 1545.41
A169: 41608 | B169: 0.002814 | C169: 0.027445 | D169: 0.01452105 | E169: 1848.4 | F169: 689.335 | G169: 1756.5 | H169: 2729.28 | I169: 982.9057 | J169: 192.4111 | K169: 316.89 | L169: 349.43 | M169: 361.46 | N169: 418.33 | O169: 1405.243 | P169: 3087.18 | Q169: 101.436 | R169: 1865.08 | S169: 253.54 | T169: 316.2 | U169: 357.80167 | V169: 413.745 | W169: #N/A | X169: #N/A | Y169: 144.1957 | Z169: 1163.64 | AA169: 1522.65
A170: 41639 | B170: 0.003799 | C170: 0.030282 | D170: 0.01388218 | E170: 1782.6 | F170: 689.425 | G170: 1742.78 | H170: 2676.43 | I170: 980.3961 | J170: 191.5678 | K170: 314.68 | L170: 347.37 | M170: 360.44 | N170: 418.3 | O170: 1412.611 | P170: 3112.84 | Q170: 101.0293 | R170: 1856.28 | S170: 252.81 | T170: 315.5 | U170: 358.82167 | V170: 415.20333 | W170: #N/A | X170: #N/A | Y170: 143.7506 | Z170: 1130.88 | AA170: 1549.65
A171: 41670 | B171: 0.003277 | C171: 0.02644 | D171: 0.01342848 | E171: 1859.45 | F171: 689.471 | G171: 1757.63 | H171: 2824.42 | I171: 999.4992 | J171: 193.9558 | K171: 319.09 | L171: 352.63 | M171: 366.83 | N171: 425.26 | O171: 1421.905 | P171: 3159.45 | Q171: 102.1837 | R171: 1885.3 | S171: 254.88 | T171: 316.9 | U171: 360.43667 | V171: 417.27167 | W171: #N/A | X171: #N/A | Y171: 145.0185 | Z171: 1183.03 | AA171: 1571.39
A172: 41698 | B172: 0.003169 | C172: 0.026476 | D172: 0.01267857 | E172: 1872.34 | F172: 689.475 | G172: 1761.18 | H172: 2847.77 | I172: 1011.2186 | J172: 194.9646 | K172: 320.08 | L172: 354.76 | M172: 370.27 | N172: 431.56 | O172: 1449.326 | P172: 3280.4 | Q172: 102.9713 | R172: 1891.79 | S172: 256.34 | T172: 317.64 | U172: 363.05667 | V172: 421.06333 | W172: #N/A | X172: #N/A | Y172: 145.9091 | Z172: 1173.04 | AA172: 1570.13
A173: 41729 | B173: 0.004183 | C173: 0.02718 | D173: 0.01259826 | E173: 1883.95 | F173: 689.504 | G173: 1754.03 | H173: 2866.52 | I173: 1012.9155 | J173: 195.6249 | K173: 319.15 | L173: 354.52 | M173: 370.08 | N173: 433.3 | O173: 1452.547 | P173: 3296.88 | Q173: 103.1676 | R173: 1885.71 | S173: 256.07 | T173: 317.19 | U173: 365.19667 | V173: 424.48833 | W173: #N/A | X173: #N/A | Y173: 145.7718 | Z173: 1126.86 | AA173: 1604.21
A174: 41759 | B174: 0.004104 | C174: 0.026459 | D174: 0.01198526 | E174: 1923.57 | F174: 689.533 | G174: 1760.41 | H174: 2923.77 | I174: 1025.0878 | J174: 196.7947 | K174: 321.39 | L174: 357.36 | M174: 374 | N174: 439.88 | O174: 1460.518 | P174: 3369.58 | Q174: 104.0176 | R174: 1903.14 | S174: 257.29 | T174: 318.28 | U174: 367.18 | V174: 427.77167 | W174: #N/A | X174: #N/A | Y174: 146.5821 | Z174: 1134.5 | AA174: 1675.93
A175: 41790 | B175: 0.00373 | C175: 0.024759 | D175: 0.0113949 | E175: 1960.23 | F175: 689.537 | G175: 1772.49 | H175: 3007.86 | I175: 1038.2916 | J175: 198.7316 | K175: 324.69 | L175: 361.25 | M175: 378.92 | N175: 447.18 | O175: 1472.461 | P175: 3462.94 | Q175: 105.2964 | R175: 1926.04 | S175: 258.96 | T175: 319.52 | U175: 370.09 | V175: 432.58 | W175: #N/A | X175: #N/A | Y175: 147.6306 | Z175: 1192.96 | AA175: 1683.84
A176: 41820 | B176: 0.004567 | C176: 0.025304 | D176: 0.01127676 | E176: 1930.67 | F176: 689.573 | G176: 1770.15 | H176: 3001.26 | I176: 1039.1906 | J176: 199.8762 | K176: 324.81 | L176: 361.09 | M176: 379.12 | N176: 448 | O176: 1484.054 | P176: 3519.24 | Q176: 105.6292 | R176: 1931.09 | S176: 259.43 | T176: 319.63 | U176: 373.20333 | V176: 437.53 | W176: #N/A | X176: #N/A | Y176: 147.9181 | Z176: 1120.07 | AA176: 1726.16
A177: 41851 | B177: 0.005276 | C177: 0.025578 | D177: 0.01111674 | E177: 2003.37 | F177: 689.593 | G177: 1765.53 | H177: 3017.8 | I177: 1041.0229 | J177: 200.9533 | K177: 323.71 | L177: 360.83 | M177: 378.91 | N177: 448 | O177: 1463.882 | P177: 3488.3 | Q177: 105.8381 | R177: 1919.76 | S177: 258.81 | T177: 319.12 | U177: 375.21667 | V177: 441.32 | W177: #N/A | X177: #N/A | Y177: 147.5563 | Z177: 1174.35 | AA177: 1776.34
...
