Workbook

Sheet private_equity
B2: Income yield | C2: {=AVERAGE(IF(ISNUMBER(ma_deal_list!K2:K799),ma_deal_list!K2:K799))/2} -> 0.035948177 | D2: US M&A deal private equity LBO small cap median LTM EBIT/EV multiple / 2
B3: Real growth rate | C3: 0.03
B4: Real unlevered return | C4: =SUM(C2:C3) -> 0.065948177
B5: Debt to Equity | C5: 0.52 | D5: Taken from AQR 2025 CMA. For the post-2008 period, we interpolate annual D/E ratios from Pitchbook/Bain. Pre-2008, we assume an aggregate D/E ratio that tapers from 300% in the 1990s to the 150% D/E reported in 2008. Although historical simulations often assume a constant D/E ratio of, say, 200% over time, PE leverage levels have been trending lower despite lower funding costs.30 In principle, higher leverage (D/E) should boost equity returns if operating income is greater than the interest expense on the debt. In reality, however, Axelson et al. (2013) showed that low funding costs and high leverage tend to coincide with hot, overpriced vintages that have lower future returns. Our usage of PE yield and multiple expansion partly captures this effect.
B6: Real cost of debt | C6: =cost_of_debt!B280 -> 0.031379267
B7: Real levered return | C7: =C4+C5*(C4-C6) -> 0.083924011
B8: Multiple expansion | C8: 0.03 | D8: Taken from AQR 2025 CMA. Multiple Expansion: The principle of meanreversion suggests that PE multiple expansion is more likely if it has an initial discount versus the market. Hence, we estimate the return from multiple expansion as the annualized return if PE multiples converged partly, say 20% of the way, toward the initial public market multiple, over the lifetime of the deal, assumed to be six years. We f loor this return at zero; that is, we do not allow for multiple compression, as there is evidence that PE GPs delay exits so as to sell at higher multiples. We assume no multiple expansion in our yieldbased frameworks for passively managed public equities and fixed income. However, we make an exception for PE due to its active ownership and some evidence that PE GPs can time deal entries and exits.33 Given the arbitrary nature of our estimate, our general skepticism around multiple expansion for any asset class, and the noise in data on PE purchase multiples, we choose to apply only a conservative, partial convergence towards the market multiple.34
B9: Gross real expected return | C9: =C7+C8 -> 0.11392401
B10: Fees | C10: 0.04
B11: Net expected real return | C11: =C9-C10 -> 0.073924011
B12: Expected inflation | C12: =cost_of_debt!D224/100 -> 0.022839
B13: Net expected return | C13: =C11+C12 -> 0.096763011
F16: yu | G16: gu | H16: ru = yu + gu | I16: D/E | J16: kd | K16: rl = ru + (D/E)*(ru - kd) | L16: m | M16: rg = rl + m | N16: f | O16: rr = rg - f | P16: i | Q16: r = rr + i
F17: Income Yield | G17: Real Growth Rate | H17: Real Unlevered Return | I17: Debt to Equity | J17: Real Cost of Debt | K17: Real levered Return | L17: Multiple Expansion | M17: Gross Real Expected Return | N17: Fees | O17: Net Expected Real Return | P17: Expected Inflation | Q17: Net Expected Return
F18: =VLOOKUP(F17,$B$2:$C$13,2,0) -> 0.035948177 | G18: =VLOOKUP(G17,$B$2:$C$13,2,0) -> 0.03 | H18: =VLOOKUP(H17,$B$2:$C$13,2,0) -> 0.065948177 | I18: =VLOOKUP(I17,$B$2:$C$13,2,0) -> 0.52 | J18: =VLOOKUP(J17,$B$2:$C$13,2,0) -> 0.031379267 | K18: =VLOOKUP(K17,$B$2:$C$13,2,0) -> 0.083924011 | L18: =VLOOKUP(L17,$B$2:$C$13,2,0) -> 0.03 | M18: =VLOOKUP(M17,$B$2:$C$13,2,0) -> 0.11392401 | ... Q18: =VLOOKUP(Q17,$B$2:$C$13,2,0) -> 0.096763011

Sheet ma_deal_list
A1: Deal Type | B1: Announce Date | C1: Target Name | D1: Acquirer Name | E1: Seller Name | F1: Announced Total Value (mil.) | G1: Payment Type | H1: Deal Status | I1: TV/EBITDA | J1: TV/EBIT | K1: EBIT/TV | L1: add D/E
A2: M&A | B2: 45723 | C2: Walgreens Boots Alliance Inc | D2: Sycamore Partners LLC | F2: 39411.56 | G2: Cash | H2: Completed | J2: 16.86 | K2: =1/J2 -> 0.059311981
A3: M&A | B3: 45845 | C3: Altice France SA/France | D3: Blackstone Inc | F3: 36360.73 | G3: Undisclosed | H3: Proposed | I3: 6.19 | J3: 15.67 | K3: =1/J3 -> 0.063816209
A4: M&A | B4: 45804 | C4: Hologic Inc | D4: Blackstone Inc,TPG Inc | F4: 16910 | G4: Cash | H4: Proposed | I4: 13.72 | J4: 19.16 | K4: =1/J4 -> 0.052192067
A5: M&A | B5: 45796 | C5: TXNM Energy Inc | D5: Blackstone Inc | F5: 11811.08 | G5: Cash | H5: Pending | I5: 13.16 | J5: 26.05 | K5: =1/J5 -> 0.038387716
A6: M&A | B6: 45890 | C6: Dayforce Inc | D6: Thoma Bravo LLC | F6: 11237.21 | G6: Cash | H6: Pending | I6: 35.07 | J6: 107.95 | K6: =1/J6 -> 0.0092635479
A7: M&A | B7: 45782 | C7: Skechers USA Inc | D7: 3G Capital Partners LP | F7: 10479.16 | G7: Cash or Stock | H7: Pending | I7: 6.87 | J7: 11.59 | K7: =1/J7 -> 0.086281277
A8: M&A | B8: 45630 | C8: ESR Group Ltd | D8: Starwood Capital Group LLC,Warburg Pincus LLC,Qatar Holding LLC,Sixth Street Partners LLC,SSW Partners LP | F8: 9381.14 | G8: Cash or Stock | H8: Completed | I8: 18.48 | J8: 20.01 | K8: =1/J8 -> 0.049975012
A9: M&A | B9: 45637 | C9: Resolution Life Group Holdings LP | D9: Nippon Life Insurance Co | E9: Blackstone Inc | F9: 8200 | G9: Cash | H9: Pending | J9: 16.17 | K9: =1/J9 -> 0.061842919
A10: M&A | B10: 45559 | C10: Smartsheet Inc | D10: Blackstone Inc,Vista Equity Partners LLC | F10: 7298.54 | G10: Cash | H10: Completed | J10: 98.53 | K10: =1/J10 -> 0.010149193
A11: M&A | B11: 45902 | C11: Air Lease Corp | D11: Sumitomo Corp,Sumitomo Mitsui Finance & Leasing Co Ltd,Brookfield Corp,Apollo Global Management Inc | F11: 7264.73 | G11: Cash | H11: Pending | I11: 2.89 | J11: 5.3 | K11: =1/J11 -> 0.18867925
A12: M&A | B12: 45840 | C12: Spectris PLC | D12: KKR & Co Inc | F12: 6466.7 | G12: Cash | H12: Pending | I12: 29.91 | J12: 48.61 | K12: =1/J12 -> 0.020571899
A13: M&A | B13: 45831 | C13: Spectris PLC | D13: Advent International Corp | F13: 6298 | G13: Cash | H13: Terminated | I13: 29.43 | J13: 47.83 | K13: =1/J13 -> 0.02090738
A14: M&A | B14: 45875 | C14: Enverus Inc | D14: Blackstone Inc | E14: Genstar Capital LLC (Fund: Genstar Capital Partners VIII LP),Hellman & Friedman LLC (Fund: Hellman & Friedman Capital Partners X LP) | F14: 6000 | G14: Cash | H14: Pending | J14: 63.6 | K14: =1/J14 -> 0.01572327
A15: M&A | B15: 45593 | C15: Yondr Group Ltd | D15: Caisse de Depot et Placement du Quebec,DigitalBridge Group Inc | E15: Cathexis Holdings LP | F15: 5800 | G15: Cash | H15: Completed | J15: 18.26 | K15: =1/J15 -> 0.054764513
A16: M&A | B16: 45722 | C16: YORK Holdings Co Ltd | D16: Bain Capital Private Equity LP | E16: Seven & i Holdings Co Ltd | F16: 5507.37 | G16: Cash | H16: Completed | J16: 27.35 | K16: =1/J16 -> 0.036563071
A17: M&A | B17: 45685 | C17: Surgery Partners Inc | D17: Bain Capital Private Equity LP | F17: 5156.99 | G17: Cash | H17: Proposed | I17: 13.2 | J17: 20.94 | K17: =1/J17 -> 0.047755492
A18: M&A | B18: 45600 | C18: Northwest Fiber LLC | D18: BCE Inc | E18: Canada Pension Plan Investment Board,British Columbia Investment Management Corp,Public Sector Pension Investment Board,Searchlight Capital Partners UK LLP (Fund: Searchlight Capital III LP),WaveDivision Capital LLC | F18: 5039.3 | G18: Cash | H18: Completed | J18: 12.87 | K18: =1/J18 -> 0.077700078
A19: M&A | B19: 45798 | C19: IO Products Inc | D19: OpenAI LLC | E19: Emerson Collective Investments LLC,Maverick Ventures Inc (Fund: Maverick Ventures Evergreen Fund),Sutter Hill Ventures LP (Fund: Bluebird Ventures I LP),SV Angel Management LLC (Fund: SV Angel Growth I LP),Thrive Capital Management LLC (Fund: Thrive Capital Partners XI) | F19: 5000 | G19: Stock | H19: Completed | J19: 12.89 | K19: =1/J19 -> 0.077579519
A20: M&A | B20: 45577 | C20: Fuji Soft Inc | D20: Bain Capital Private Equity LP | F20: 4422.44 | G20: Cash | H20: Terminated | I20: 26.5 | J20: 31.86 | K20: =1/J20 -> 0.03138732
A21: M&A | B21: 45695 | C21: SolarWinds Corp | D21: Turn/River Capital | F21: 4217.81 | G21: Cash | H21: Completed | J21: 41.85 | K21: =1/J21 -> 0.023894863
A22: M&A | B22: 45740 | C22: Dun & Bradstreet Holdings Inc | D22: Clearlake Capital Group LP | F22: 4039.87 | G22: Cash | H22: Completed | I22: 5.16 | J22: 20.74 | K22: =1/J22 -> 0.048216008
A23: M&A | B23: 45572 | C23: Barnes Group Inc | D23: Apollo Global Management Inc | F23: 3511.94 | G23: Cash | H23: Completed | I23: 17.15 | J23: 39.46 | K23: =1/J23 -> 0.025342119
A24: M&A | B24: 45637 | C24: Patterson Cos Inc | D24: Patient Square Capital LP | F24: 3423.33 | G24: Cash | H24: Completed | I24: 9.02 | J24: 13.54 | K24: =1/J24 -> 0.073855244
A25: M&A | B25: 45728 | C25: Gerresheimer AG | D25: Warburg Pincus LLC | F25: 3390.55 | G25: Cash | H25: Withdrawn | I25: 7.85 | J25: 15.74 | K25: =1/J25 -> 0.063532402
A26: M&A | B26: 45695 | C26: Mitsubishi Tanabe Pharma Corp | D26: Bain Capital Private Equity LP | E26: Mitsubishi Chemical Group Corp | F26: 3362.43 | G26: Cash | H26: Pending | J26: 11.33 | K26: =1/J26 -> 0.088261253
A27: M&A | B27: 45875 | C27: TechnoPro Holdings Inc | D27: Blackstone Inc | F27: 3319.8 | G27: Cash | H27: Pending | I27: 19.42 | J27: 22.32 | K27: =1/J27 -> 0.044802867
A28: M&A | B28: 45599 | C28: Air Transport Services Group Inc | D28: Stonepeak Partners LP | F28: 3167.19 | G28: Cash | H28: Completed | I28: 5.62 | J28: 15.85 | K28: =1/J28 -> 0.063091483
A29: M&A | B29: 45761 | C29: OSTTRA | D29: KKR & Co Inc | E29: S&P Global Inc,CME Group Inc | F29: 3100 | G29: Cash | H29: Pending | J29: 12.87 | K29: =1/J29 -> 0.077700078
A30: M&A | B30: 45783 | C30: Exafunction Inc | D30: OpenAI Inc | E30: Kleiner Perkins Caufield & Byers LLC (Fund: Kleiner Perkins Caufield & Byers XX LLC),Founders Fund Management LLC/The (Fund: Founders Fund Growth II LP),Greenoaks Capital Management LLC (Fund: Greenoaks Capital Opportunities Fund V LP),General Catalyst Partners LLC (Fund: General Catalyst Gro... | F30: 3000 | G30: Cash | H30: Pending | J30: 13.75 | K30: =1/J30 -> 0.072727273
A31: M&A | B31: 45691 | C31: Triumph Group Inc | D31: Warburg Pincus LLC (Fund: Warburg Pincus Global Growth II),Berkshire Partners LLC (Fund: Berkshire Fund XI LP) | F31: 2871.96 | G31: Cash | H31: Completed | I31: 22.82 | J31: 33.22 | K31: =1/J31 -> 0.030102348
A32: M&A | B32: 45726 | C32: Moveworks Inc | D32: ServiceNow Inc | E32: Comerica Inc,Kleiner Perkins Caufield & Byers LLC,Lightspeed Management Co LLC,Alkeon Capital Management LLC,Tiger Global Management LLC,Bain Capital Venture Partners LLC,Sapphire Ventures LLC,ICONIQ Capital LLC | F32: 2850 | G32: Cash | H32: Pending | J32: 63.6 | K32: =1/J32 -> 0.01572327
A33: M&A | B33: 45744 | C33: Topcon Corp | D33: KKR & Co Inc | F33: 2844.65 | G33: Cash | H33: Pending | I33: 16.74 | J33: 38.08 | K33: =1/J33 -> 0.026260504
A34: M&A | B34: 45756 | C34: Karo Pharma AB | D34: KKR & Co Inc | E34: EQT AB | F34: 2755 | G34: Cash | H34: Pending | I34: 36.17 | J34: 11.33 | K34: =1/J34 -> 0.088261253
A35: M&A | B35: 45611 | C35: Fuji Soft Inc | D35: KKR & Co Inc | F35: 2736.03 | G35: Cash | H35: Completed | I35: 25.74 | J35: 30.95 | K35: =1/J35 -> 0.032310178
A36: M&A | B36: 45903 | C36: DiMeo Schneider & Associates LLC,Newport Private Wealth Inc,Wealthspire Advisors LP | D36: Madison Dearborn Partners LLC | E36: Aon PLC | F36: 2700 | G36: Cash | H36: Pending | K36: =1/J36 -> #VALUE!
A37: M&A | B37: 45628 | C37: Sunstone Hotel Investors Inc | D37: Trinity Investments LLC | F37: 2611.72 | G37: Cash | H37: Proposed | I37: 10.02 | J37: 22.01 | K37: =1/J37 -> 0.045433894
A38: M&A | B38: 45670 | C38: Scorpion Therapeutics Inc | D38: Eli Lilly & Co | E38: Wellington Management Group LLP,Mass General Brigham Inc,Janus Henderson Group PLC,Willett Advisors LLC,Boxer Capital LLC,Invus Group LLC/The (Fund: IFA PE Fund II LP),Omega Funds Investment Ltd,Logos Capital Partners Sarl (Fund: Logos Global Opportunities I),Woodline Partners LP,EcoR1 Capita... | F38: 2500 | G38: Cash | H38: Pending | J38: 23.39 | K38: =1/J38 -> 0.042753313
A39: M&A | B39: 45882 | C39: Sapiens International Corp NV | D39: Advent International Corp | F39: 2283.82 | G39: Cash | H39: Pending | I39: 20.73 | J39: 26.6 | K39: =1/J39 -> 0.037593985
A40: M&A | B40: 45602 | C40: Retail Opportunity Investments Corp | D40: Blackstone Inc | F40: 2251.36 | G40: Cash | H40: Completed | I40: 10.44 | J40: 20.5 | K40: =1/J40 -> 0.048780488
...

Sheet cost_of_debt
A1: Date | B1: Index OAS to Treasury Curve Basis Points | C1: Nominal SOFR | D1: Expected inflation (US 10Y breakeven) | E1: Real SOFR
A2: 45525 | B2: 316.7254 | C2: 5.31 | D2: 2.0808 | E2: =C2-D2 -> 3.2292
A3: 45526 | B3: 310.83441 | C3: 5.31 | D3: 2.102 | E3: =C3-D3 -> 3.208
A4: 45527 | B4: 309.6752 | C4: 5.33 | D4: 2.123 | E4: =C4-D4 -> 3.207
A5: 45530 | B5: 305.44131 | C5: 5.34 | D5: 2.1439 | E5: =C5-D5 -> 3.1961
A6: 45531 | B6: 307.75989 | C6: 5.35 | D6: 2.1522 | E6: =C6-D6 -> 3.1978
A7: 45532 | B7: 307.65741 | C7: 5.35 | D7: 2.1535 | E7: =C7-D7 -> 3.1965
A8: 45533 | B8: 304.3891 | C8: 5.33 | D8: 2.1597 | E8: =C8-D8 -> 3.1703
A9: 45534 | B9: 301.6766 | C9: 5.32 | D9: 2.152 | E9: =C9-D9 -> 3.168
A10: 45537 | B10: 304.86359 | C10: 5.32 | D10: #N/A | E10: =C10-D10 -> #N/A
A11: 45538 | B11: 320.1131 | C11: 5.34 | D11: 2.1131 | E11: =C11-D11 -> 3.2269
A12: 45539 | B12: 324.2836 | C12: 5.35 | D12: 2.0614 | E12: =C12-D12 -> 3.2886
A13: 45540 | B13: 319.0123 | C13: 5.35 | D13: 2.0485 | E13: =C13-D13 -> 3.3015
A14: 45541 | B14: 326.7529 | C14: 5.34 | D14: 2.0354 | E14: =C14-D14 -> 3.3046
A15: 45544 | B15: 324.80969 | C15: 5.34 | D15: 2.044 | E15: =C15-D15 -> 3.296
A16: 45545 | B16: 334.8508 | C16: 5.33 | D16: 2.0308 | E16: =C16-D16 -> 3.2992
A17: 45546 | B17: 334.19479 | C17: 5.32 | D17: 2.0436 | E17: =C17-D17 -> 3.2764
A18: 45547 | B18: 329.88611 | C18: 5.33 | D18: 2.0642 | E18: =C18-D18 -> 3.2658
A19: 45548 | B19: 326.6824 | C19: 5.33 | D19: 2.0818 | E19: =C19-D19 -> 3.2482
A20: 45551 | B20: 324.8692 | C20: 5.38 | D20: 2.0895 | E20: =C20-D20 -> 3.2905
A21: 45552 | B21: 316.95999 | C21: 5.38 | D21: 2.1084 | E21: =C21-D21 -> 3.2716
A22: 45553 | B22: 311.98969 | C22: 5.33 | D22: 2.1114 | E22: =C22-D22 -> 3.2186
... A39: 45576 | B39: 293.93631 | C39: 4.81 | D39: 2.3324 | E39: =C39-D39 -> 2.4776
A40: 45579 | B40: 293.93631 | C40: 4.81 | D40: #N/A | E40: =C40-D40 -> #N/A
A41: 45580 | B41: 288.8512 | C41: 4.86 | D41: 2.2778 | E41: =C41-D41 -> 2.5822
A42: 45581 | B42: 286.4241 | C42: 4.86 | D42: 2.2709 | E42: =C42-D42 -> 2.5891
A43: 45582 | B43: 284.185 | C43: 4.85 | D43: 2.3105 | E43: =C43-D43 -> 2.5395
A44: 45583 | B44: 285.35751 | C44: 4.84 | D44: 2.3064 | E44: =C44-D44 -> 2.5336
A45: 45586 | B45: 282.92151 | C45: 4.82 | D45: 2.3178 | E45: =C45-D45 -> 2.5022
A46: 45587 | B46: 287.6691 | C46: 4.83 | D46: 2.3368 | E46: =C46-D46 -> 2.4932
A47: 45588 | B47: 289.6879 | C47: 4.83 | D47: 2.3209 | E47: =C47-D47 -> 2.5091
A48: 45589 | B48: 288.8981 | C48: 4.83 | D48: 2.2985 | E48: =C48-D48 -> 2.5315
A49: 45590 | B49: 285.79321 | C49: 4.83 | D49: 2.2938 | E49: =C49-D49 -> 2.5362
A50: 45593 | B50: 279.58758 | C50: 4.82 | D50: 2.294 | E50: =C50-D50 -> 2.526
A51: 45594 | B51: 281.71579 | C51: 4.82 | D51: 2.3137 | E51: =C51-D51 -> 2.5063
A52: 45595 | B52: 276.27759 | C52: 4.81 | D52: 2.3469 | E52: =C52-D52 -> 2.4631
... A59: 45604 | B59: 256.27801 | C59: 4.6 | D59: 2.3631 | E59: =C59-D59 -> 2.2369
A60: 45607 | B60: 256.27801 | C60: 4.6 | D60: #N/A | E60: =C60-D60 -> #N/A
A61: 45608 | B61: 252.6678 | C61: 4.6 | D61: 2.3676 | E61: =C61-D61 -> 2.2324
A62: 45609 | B62: 255.22031 | C62: 4.59 | D62: 2.3658 | E62: =C62-D62 -> 2.2242
...

Sheet real_estate
B2: NOI yield | C2: 0.0469
B3: CapEx | C3: =C2/3 -> 0.015633333
B4: Cashflow yield | C4: =C2-C3 -> 0.031266667
B5: Real growth | C5: 0
B6: Unlevered real ER | C6: =C4+C5 -> 0.031266667
B7: Expected inflation | C7: =cost_of_debt!D224/100 -> 0.022839
B8: Unlevered nominal ER | C8: =C6+C7 -> 0.054105667
D13: NOI yield | E13: CapEx (~NOI/3) | F13: Cashflow yield | G13: Real growth | H13: Unlevered real ER | I13: Expected inflation | J13: Unlevered nominal ER
D14: =C2 -> 0.0469 | E14: =C3 -> 0.015633333 | F14: =C4 -> 0.031266667 | G14: =C5 -> 0 | H14: =C6 -> 0.031266667 | I14: =C7 -> 0.022839 | J14: =C8 -> 0.054105667

Sheet private_credit
B2: HY credit expected real return | C2: 0.051761 | D2: from my CMA framework fixed income part, HY intermediate bonds expected return (arithmetic) - expected inflation 2.28%)
B3: Cash real return | C3: =cash!F308 -> 0.016420667
B4: HY credit excess real return | C4: =C2-C3 -> 0.035340333
B5: Leverage multiplier | C5: 1.2 | D5: Taken from Block et al. 2023
B6: Expected PC real return (arithmetic average) | C6: =C3+C4*C5 -> 0.058829067
B7: Variance of levered HY credit return (L^2*Var(HY)) | C7: =D7^2*C5 -> 0.018636447 | D7: 0.12462092 | E7: <--- HY (intermediate) standard deviation over 1987-2025, based on annual returns
B8: Expected PC real return (geometric average) | C8: =C6-C7/2 -> 0.049510843
B9: Expected inflation | C9: =cost_of_debt!D224/100 -> 0.022839
B10: Expected PC nominal return (geometric average) | C10: =(1+C8)*(1+C9)-1 -> 0.073480621
D13: HY credit expected real return | E13: Cash real return | F13: HY credit excess real return | G13: Leverage multiplier | H13: Expected PC real return (arithmetic average) | I13: Variance of levered HY credit return (L^2*Var(HY)) | J13: Expected PC real return (geometric average) | K13: Expected inflation | L13: Expected PC nominal return (geometric average)
D14: 0.051761 | E14: 0.016420667 | F14: 0.035340333 | G14: 1.2 | H14: 0.058829067 | I14: 0.018636447 | J14: 0.049510843 | K14: 0.022839 | L14: 0.073480621
B25: Geometric VS arithmetic
B26: Year | C26: 1 | D26: 2 | E26: 3 | F26: 4 | G26: 5 | H26: 6
B27: Return | C27: 0.015 | D27: 0.1 | E27: -0.12 | F27: 0.2 | G27: 0.012 | H27: 0.06
B29: Arithmetic | C29: =AVERAGE(C27:H27) -> 0.0445
B30: Geometric | C30: {=(PRODUCT(1+C27:H27))^(1/6)-1} -> 0.039923767
B31: Variance/2 | C31: =_xlfn.VAR.P(C27:H27)/2 -> 0.0047072917
B32: A - V/2 ~ G | C32: =C29-C31 -> 0.039792708
B35: Leverage
B36: Rfr | C36: 0.02
B37: HY spread | C37: 0.04
B38: Total yield | C38: =SUM(C36:C37) -> 0.06
B40: Equity | C40: 100
B41: Leverage | C41: 0.2
B42: Total investment | C42: =C40*(1+C41) -> 120
B43: Leverage multiplier | C43: =C42/C40 -> 1.2
B45: Total return | C45: =C42*C38 -> 7.2
B46: Pay cash | C46: =C40*C41*C36 -> 0.4
B47: Return to equity | C47: =C45-C46 -> 6.8
B49: Return % | C49: =C47/C40 -> 0.068
B50: Excess return * leverage multiplier | C50: =C37*C43+C36 -> 0.068
C51: =C50=C49 -> TRUE

Sheet cash
A1: Date | B1: UST, 3M | C1: UST, 10Y
A2: 36525 | B2: 0.05411 | C2: 0.06592
A3: 36556 | B3: 0.05692 | C3: 0.06665
A4: 36585 | B4: 0.05781 | C4: 0.06409
A5: 36616 | B5: 0.05871 | C5: 0.06004
A6: 36646 | B6: 0.05829 | C6: 0.06212
A7: 36677 | B7: 0.05619 | C7: 0.06272
A8: 36707 | B8: 0.05854 | C8: 0.06031
A9: 36738 | B9: 0.06219 | C9: 0.06031
A10: 36769 | B10: 0.06306 | C10: 0.05725
A11: 36799 | B11: 0.06209 | C11: 0.05802
A12: 36830 | B12: 0.06389 | C12: 0.05751
A13: 36860 | B13: 0.06202 | C13: 0.05468
... A306: 45777 | B306: 0.04288 | C306: 0.041619
A307: 45808 | B307: 0.04342 | C307: 0.044004 | D307: Next 10Y Avg. Forecast Short Rate | E307: Expected inflation | F307: Expected real cash return
A308: 45838 | B308: 0.04301 | C308: 0.042769 | D308: 0.032 | E308: =cost_of_debt!D224/100 -> 0.022839 | F308: =AVERAGE(B308:D308)-E308 -> 0.016420667
D309: Taken from AQR which itself uses Consensus Economics forecast estimate
