Workbook

Sheet Timeseries
A1: Date | B1: Stock_1 | C1: Stock_2 | D1: Stock_3 | E1: Stock_4 | F1: Stock_5 | G1: Stock_6 | H1: Stock_7 | I1: Stock_8 | J1: Stock_9 | K1: Stock_10 | L1: Bond_10Y | M1: Stock_Index
A2: 42035 | B2: -0.024185222 | C2: 0.086116494 | D2: 0.20749862 | E2: 0.23616686 | F2: -0.072663996 | G2: 0.079694311 | H2: 0.02148844 | I2: -0.014563967 | J2: 0.36726102 | K2: 0.19249322 | L2: 0.014901425 | M2: 0.12352719 | N2: {=SUMPRODUCT(1+B2:K2,$B$124:$K$124)-1} -> 0.12352719
A3: 42063 | B3: -0.28067557 | C3: 0.034777 | D3: 0.24602997 | E3: 0.046934344 | F3: -0.36535199 | G3: -0.21425038 | H3: 0.082871639 | I3: -0.22069285 | J3: -0.039100388 | K3: 0.010555007 | L3: -0.004147929 | M3: -0.065941036 | N3: {=SUMPRODUCT(1+B3:K3,$B$124:$K$124)-1} -> -0.065941036
A4: 42094 | B4: 0.023830451 | C4: 0.17096898 | D4: -0.35956126 | E4: 0.028738702 | F4: 0.16405904 | G4: 0.010342506 | H4: 0.3919147 | I4: -0.066888532 | J4: 0.10712683 | K4: 0.23042738 | L4: 0.019430656 | M4: 0.076414286 | N4: {=SUMPRODUCT(1+B4:K4,$B$124:$K$124)-1} -> 0.076414286
A5: 42124 | B5: 0.069780484 | C5: -0.36550467 | D5: 0.069709891 | E5: -0.097183049 | F5: -0.25072273 | G5: 0.0016549517 | H5: -0.10887453 | I5: -0.2791566 | J5: -0.11339788 | K5: -0.1884175 | L5: 0.045690896 | M5: -0.13929402 | N5: {=SUMPRODUCT(1+B5:K5,$B$124:$K$124)-1} -> -0.13929402
A6: 42155 | B6: 0.077519962 | C6: 0.17079666 | D6: 0.34484241 | E6: -0.1276944 | F6: 0.40627343 | G6: -0.28154044 | H6: 0.039364195 | I6: 0.16668932 | J6: 0.1034817 | K6: -0.040877661 | L6: -0.0070246012 | M6: 0.094203459 | N6: {=SUMPRODUCT(1+B6:K6,$B$124:$K$124)-1} -> 0.094203459
A7: 42185 | B7: 0.20423396 | C7: 0.1783696 | D7: 0.17558767 | E7: 0.3622999 | F7: 0.31301518 | G7: 0.15058121 | H7: 0.36354643 | I7: 0.3139737 | J7: 0.36523139 | K7: 0.38415038 | L7: -0.0070241087 | M7: 0.28452163 | N7: {=SUMPRODUCT(1+B7:K7,$B$124:$K$124)-1} -> 0.28452163
A8: 42216 | B8: -0.21185717 | C8: -0.17586398 | D8: 0.052878158 | E8: 0.040272235 | F8: -0.041335708 | G8: -0.00083822618 | H8: 0.09112242 | I8: -0.22904085 | J8: 0.006458779 | K8: -0.10108303 | L8: 0.047376384 | M8: -0.062757314 | N8: {=SUMPRODUCT(1+B8:K8,$B$124:$K$124)-1} -> -0.062757314
A9: 42247 | B9: -0.08548363 | C9: 0.12265667 | D9: 0.095049437 | E9: 0.087064071 | F9: 0.18355868 | G9: -0.017909786 | H9: 0.043901655 | I9: -0.12512567 | J9: 0.0023233048 | K9: -0.065671001 | L9: 0.023023042 | M9: 0.024477828 | N9: {=SUMPRODUCT(1+B9:K9,$B$124:$K$124)-1} -> 0.024477828
A10: 42277 | B10: 0.020473565 | C10: 0.097256537 | D10: -0.14486505 | E10: 0.3049078 | F10: -0.17613416 | G10: -0.2323955 | H10: 0.17308299 | I10: 0.14314555 | J10: 0.094754848 | K10: 0.10313046 | L10: -0.014084232 | M10: 0.030530987 | N10: {=SUMPRODUCT(1+B10:K10,$B$124:$K$124)-1} -> 0.030530987
A11: 42308 | B11: -0.051185648 | C11: -0.19210413 | D11: -0.034611735 | E11: -0.1364683 | F11: 0.12567903 | G11: -0.054654929 | H11: -0.16814723 | I11: -0.11712453 | J11: 0.017700926 | K11: -0.14148291 | L11: 0.016276801 | M11: -0.071050493 | N11: {=SUMPRODUCT(1+B11:K11,$B$124:$K$124)-1} -> -0.071050493
A12: 42338 | B12: -0.28968458 | C12: -0.15562072 | D12: -0.1750382 | E12: -0.26631244 | F12: -0.29013037 | G12: -0.19538023 | H12: -0.37969627 | I12: -0.40612522 | J12: -0.29447856 | K12: -0.25664878 | L12: -0.013902531 | M12: -0.26211132 | N12: {=SUMPRODUCT(1+B12:K12,$B$124:$K$124)-1} -> -0.26211132
A13: 42369 | B13: 0.047918663 | C13: 0.23374546 | D13: 0.1428191 | E13: -0.033858952 | F13: -0.019179477 | G13: -0.19907825 | H13: 0.00054141457 | I13: -0.033253051 | J13: 0.045839817 | K13: -0.15275503 | L13: -0.013971893 | M13: 0.0026585589 | N13: {=SUMPRODUCT(1+B13:K13,$B$124:$K$124)-1} -> 0.0026585589
... A121: 45657 | B121: 0.14292624 | C121: 0.24668164 | D121: 0.28579183 | E121: 0.036950347 | F121: 0.11628757 | G121: 0.21370057 | H121: 0.062948317 | I121: 0.35149835 | J121: 0.18770818 | K121: 0.26768585 | L121: 0.022557991 | M121: 0.20335485 | N121: {=SUMPRODUCT(1+B121:K121,$B$124:$K$124)-1} -> 0.20335485
A123: Correl with bond | B123: =CORREL(B2:B121,$L$2:$L$121) -> 0.13339309 | C123: =CORREL(C2:C121,$L$2:$L$121) -> 0.14166519 | D123: =CORREL(D2:D121,$L$2:$L$121) -> 0.24900995 | E123: =CORREL(E2:E121,$L$2:$L$121) -> 0.17006528 | F123: =CORREL(F2:F121,$L$2:$L$121) -> 0.25087745 | G123: =CORREL(G2:G121,$L$2:$L$121) -> 0.32978254 | H123: =CORREL(H2:H121,$L$2:$L$121) -> 0.13837369 | I123: =CORREL(I2:I121,$L$2:$L$121) -> -0.079159385 | ... K123: =CORREL(K2:K121,$L$2:$L$121) -> 0.19779888 | M123: =CORREL(M2:M121,$L$2:$L$121) -> 0.25266587
A124: Weights | B124: 0.08 | C124: 0.12 | D124: 0.1 | E124: 0.07 | F124: 0.11 | G124: 0.09 | H124: 0.06 | I124: 0.08 | J124: 0.13 | K124: 0.16
J125: Average | K125: =AVERAGE(B123:K123) -> 0.16206999 | L125: DR
J126: Weighted average | K126: =SUMPRODUCT(B123:K123,B124:K124) -> 0.1669274 | L126: =Summary!B4 -> 1.4623508 | M126: =K126*Summary!B4 -> 0.2441064
L127: the aggregate (index) correlation with bonds is a weighted average of the individual correlations, multiplied by a diversification factor (the “correlation leverage”).

Sheet PerStock
B1: Weight | C1: Sigma_hat | D1: Phi_i = Sigma_i / Sigma_p | E1: Omega_i | F1: IndivCorr_iB (sample)
A2: Stock_1 | B2: 0.08 | C2: 0.16737885 | D2: 1.183083 | E2: 0.064722257 | F2: 0.13339309
A3: Stock_2 | B3: 0.12 | C3: 0.21667163 | D3: 1.5314989 | E3: 0.12567428 | F3: 0.14166519
A4: Stock_3 | B4: 0.1 | C4: 0.23146253 | D4: 1.6360454 | E4: 0.11187777 | F4: 0.24900995
A5: Stock_4 | B5: 0.07 | C5: 0.18577292 | D5: 1.3130977 | E5: 0.062855536 | F5: 0.17006528
A6: Stock_5 | B6: 0.11 | C6: 0.20343514 | D6: 1.4379395 | E6: 0.10816375 | F6: 0.25087745
A7: Stock_6 | B7: 0.09 | C7: 0.24580919 | D7: 1.7374518 | E7: 0.10693102 | F7: 0.32978254
A8: Stock_7 | B8: 0.06 | C8: 0.19254968 | D8: 1.3609979 | E8: 0.05584151 | F8: 0.13837369
A9: Stock_8 | B9: 0.08 | C9: 0.19695629 | D9: 1.3921451 | E9: 0.076159298 | F9: -0.079159385
A10: Stock_9 | B10: 0.13 | C10: 0.19324931 | D10: 1.3659431 | E10: 0.12142955 | F10: 0.088893247
A11: Stock_10 | B11: 0.16 | C11: 0.21509322 | D11: 1.5203423 | E11: 0.16634502 | F11: 0.19779888

Sheet Summary
B1: Value
A2: Direct aggregate corr (Index vs Bond) | B2: 0.25266587
A3: Formula aggregate corr (DR * sum omega_i * rho_iB) | B3: 0.25266587
A4: Diversification Ratio (DR) | B4: 1.4623508
A5: Index vol (sample) | B5: 0.14147684
A6: Cap-weighted avg indiv corr (sum w_i * rho_iB) | B6: 0.1669274

Sheet JPM Corr
C2: U.S. Inflation | D2: U.S. Cash | E2: U.S. Intermediate Treasuries | F2: U.S. Long Treasuries | G2: TIPS | H2: U.S. Aggregate Bonds | I2: U.S. Securitized | J2: U.S. Short Duration Government/Credit | K2: U.S. Long Duration Government/Credit | L2: U.S. Inv Grade Corporate Bonds | M2: U.S. Long Corporate Bonds | N2: U.S. High Yield Bonds | O2: U.S. Leveraged Loans | P2: World Government Bonds hedged | Q2: World Government Bonds | R2: World ex-U.S. Government Bonds hedged | S2: World ex-U.S. Government Bonds | T2: Emerging Markets Sovereign Debt | U2: Emerging Markets Local Currency Debt | V2: Emerging Markets Corporate Bonds | W2: U.S. Muni 1-15 Yr Blend | X2: U.S. Muni High Yield | Y2: U.S. Large Cap | Z2: U.S. Mid Cap | AA2: U.S. Small Cap | AB2: Euro Area Large Cap | AC2: Japanese Equity | AD2: Hong Kong Equity | AE2: UK Large Cap | AF2: EAFE Equity | AG2: Chinese Domestic Equity | AH2: Emerging Markets Equity | AI2: AC Asia ex-Japan Equity | AJ2: AC World Equity | AK2: U.S. Equity Value Factor | AL2: U.S. Equity Momentum Factor | AM2: U.S. Equity Quality Factor | AN2: U.S. Equity Minimum Volatility Factor | AO2: U.S. Equity Dividend Yield Factor | AP2: Global Convertible Bonds hedged | AQ2: U.S. Core Real Estate | AR2: U.S. Value-Added Real Estate | AS2: European Core Real Estate | AT2: Asia Pacific Core Real Estate | AU2: U.S. REITs | AV2: Commercial Mortgage Loans | AW2: Global Core Infrastructure | AX2: Global Core Transport | AY2: Global Timberland | AZ2: Commodities | BA2: Gold | BB2: Private Equity | BC2: Venture Capital | BD2: Diversified Hedge Funds | BE2: Event Driven Hedge Funds | BF2: Long Bias Hedge Funds | BG2: Relative Value Hedge Funds | BH2: Macro Hedge Funds | BI2: Direct Lending
B3: U.S. Inflation | C3: 1
B4: U.S. Cash | C4: -0.03 | D4: 1
B5: U.S. Intermediate Treasuries | C5: -0.27 | D5: 0.17 | E5: 1
B6: U.S. Long Treasuries | C6: -0.22 | D6: 0.03 | E6: 0.83 | F6: 1
B7: TIPS | C7: -0.02 | D7: 0.02 | E7: 0.62 | F7: 0.6 | G7: 1
B8: U.S. Aggregate Bonds | C8: -0.24 | D8: 0.08 | E8: 0.84 | F8: 0.85 | G8: 0.76 | H8: 1
B9: U.S. Securitized | C9: -0.23 | D9: 0.1 | E9: 0.78 | F9: 0.74 | G9: 0.69 | H9: 0.93 | I9: 1
B10: U.S. Short Duration Government/Credit | C10: -0.3 | D10: 0.28 | E10: 0.84 | F10: 0.59 | G10: 0.63 | H10: 0.82 | I10: 0.76 | J10: 1
B11: U.S. Long Duration Government/Credit | C11: -0.22 | D11: 0.02 | E11: 0.74 | F11: 0.9 | G11: 0.69 | H11: 0.94 | I11: 0.81 | J11: 0.66 | K11: 1
B12: U.S. Inv Grade Corporate Bonds | C12: -0.19 | D12: 0.01 | E12: 0.52 | F12: 0.6 | G12: 0.72 | H12: 0.87 | I12: 0.75 | J12: 0.66 | K12: 0.85 | L12: 1
B13: U.S. Long Corporate Bonds | C13: -0.19 | D13: 0 | E13: 0.51 | F13: 0.67 | G13: 0.67 | H13: 0.87 | I13: 0.74 | J13: 0.6 | K13: 0.91 | L13: 0.97 | M13: 1
B14: U.S. High Yield Bonds | C14: 0 | D14: 0.05 | E14: -0.02 | F14: 0 | G14: 0.48 | H14: 0.38 | I14: 0.38 | J14: 0.28 | K14: 0.33 | L14: 0.66 | M14: 0.6 | N14: 1
B15: U.S. Leveraged Loans | C15: 0.18 | D15: 0.05 | E15: -0.37 | F15: 0.28 | G15: 0.18 | H15: 0.03 | I15: 0.04 | J15: 0.05 | K15: 0.03 | L15: 0.36 | M15: 0.31 | N15: 0.77 | O15: 1
B16: World Government Bonds hedged | C16: -0.29 | D16: 0.1 | E16: 0.86 | F16: 0.87 | G16: 0.62 | H16: 0.87 | I16: 0.78 | J16: 0.72 | K16: 0.84 | L16: 0.66 | M16: 0.68 | N16: 0.12 | O16: 0.2 | P16: 1
B17: World Government Bonds | C17: -0.17 | D17: 0.09 | E17: 0.75 | F17: 0.66 | G17: 0.69 | H17: 0.8 | I17: 0.72 | J17: 0.74 | K17: 0.74 | L17: 0.69 | M17: 0.68 | N17: 0.33 | O17: 0.05 | P17: 0.72 | Q17: 1
B18: World ex-U.S. Government Bonds hedged | C18: -0.28 | D18: 0.1 | E18: 0.72 | F18: 0.74 | G18: 0.58 | H18: 0.79 | I18: 0.7 | J18: 0.63 | K18: 0.77 | L18: 0.64 | M18: 0.66 | N18: 0.19 | O18: -0.1 | P18: 0.96 | Q18: 0.66 | R18: 1
B19: World ex-U.S. Government Bonds | C19: -0.16 | D19: 0.08 | E19: 0.65 | F19: 0.55 | G19: 0.65 | H19: 0.74 | I19: 0.67 | J19: 0.68 | K19: 0.68 | L19: 0.68 | M19: 0.67 | N19: 0.4 | O19: 0.04 | P19: 0.64 | Q19: 0.98 | R19: 0.61 | S19: 1
B20: Emerging Markets Sovereign Debt | C20: -0.14 | D20: 0.03 | E20: 0.31 | F20: 0.34 | G20: 0.62 | H20: 0.66 | I20: 0.6 | J20: 0.49 | K20: 0.62 | L20: 0.82 | M20: 0.78 | N20: 0.75 | O20: 0.45 | P20: 0.44 | Q20: 0.6 | R20: 0.46 | S20: 0.64 | T20: 1
B21: Emerging Markets Local Currency Debt | C21: -0.05 | D21: 0.09 | E21: 0.22 | F21: 0.18 | G21: 0.45 | H21: 0.47 | I21: 0.42 | J21: 0.41 | K21: 0.43 | L21: 0.61 | M21: 0.58 | N21: 0.62 | O21: 0.35 | P21: 0.26 | Q21: 0.61 | R21: 0.28 | S21: 0.67 | T21: 0.81 | U21: 1
B22: Emerging Markets Corporate Bonds | C22: -0.07 | D22: 0.02 | E22: 0.19 | F22: 0.23 | G22: 0.55 | H22: 0.57 | I22: 0.5 | J22: 0.44 | K22: 0.52 | L22: 0.8 | M22: 0.73 | N22: 0.73 | O22: 0.57 | P22: 0.31 | Q22: 0.48 | R22: 0.32 | S22: 0.51 | T22: 0.89 | U22: 0.73 | V22: 1
B23: U.S. Muni 1-15 Yr Blend | C23: -0.17 | D23: 0.06 | E23: 0.52 | F23: 0.51 | G23: 0.58 | H23: 0.72 | I23: 0.69 | J23: 0.55 | K23: 0.64 | L23: 0.69 | M23: 0.66 | N23: 0.42 | O23: 0.18 | P23: 0.6 | Q23: 0.55 | R23: 0.59 | S23: 0.54 | T23: 0.63 | U23: 0.39 | V23: 0.5 | W23: 1
B24: U.S. Muni High Yield | C24: 0.17 | D24: 0.05 | E24: 0.15 | F24: 0.25 | G24: 0.47 | H24: 0.43 | I24: 0.43 | J24: 0.2 | K24: 0.39 | L24: 0.55 | M24: 0.49 | N24: 0.5 | O24: 0.49 | P24: 0.29 | Q24: 0.26 | R24: 0.3 | S24: 0.28 | T24: 0.57 | U24: 0.31 | V24: 0.55 | W24: 0.64 | X24: 1
B25: U.S. Large Cap | C25: 0 | D25: 0 | E25: -0.06 | F25: 0.03 | G25: 0.31 | H25: 0.26 | I25: 0.26 | J25: 0.12 | K25: 0.25 | L25: 0.49 | M25: 0.47 | N25: 0.74 | O25: 0.58 | P25: 0.09 | Q25: 0.29 | R25: 0.16 | S25: 0.37 | T25: 0.62 | U25: 0.6 | V25: 0.57 | W25: 0.23 | X25: 0.33 | Y25: 1
B26: U.S. Mid Cap | C26: 0 | D26: 0.04 | E26: -0.1 | F26: 0.05 | G26: 0.31 | H26: 0.25 | I26: 0.25 | J26: 0.1 | K26: 0.24 | L26: 0.5 | M26: 0.47 | N26: 0.78 | O26: 0.62 | P26: 0.05 | Q26: 0.26 | R26: 0.13 | S26: 0.34 | T26: 0.62 | U26: 0.6 | V26: 0.58 | W26: 0.25 | X26: 0.33 | Y26: 0.96 | Z26: 1
B27: U.S. Small Cap | C27: -0.03 | D27: 0.05 | E27: -0.13 | F27: 0.1 | G27: 0.22 | H27: 0.18 | I27: 0.2 | J27: 0.05 | K27: 0.17 | L27: 0.4 | M27: 0.38 | N27: 0.71 | O27: 0.55 | P27: 0 | Q27: 0.2 | R27: 0.08 | S27: 0.27 | T27: 0.53 | U27: 0.54 | V27: 0.48 | W27: 0.18 | X27: 0.24 | Y27: 0.9 | Z27: 0.95 | AA27: 1
B28: Euro Area Large Cap | C28: -0.02 | D28: 0.05 | E28: -0.02 | F28: 0.04 | G28: 0.29 | H28: 0.29 | I28: 0.29 | J28: 0.22 | K28: 0.26 | L28: 0.5 | M28: 0.48 | N28: 0.73 | O28: 0.52 | P28: 0.06 | Q28: 0.41 | R28: 0.12 | S28: 0.49 | T28: 0.68 | U28: 0.73 | V28: 0.62 | W28: 0.27 | X28: 0.3 | Y28: 0.85 | Z28: 0.84 | AA28: 0.77 | AB28: 1
B29: Japanese Equity | C29: -0.07 | D29: 0 | E29: -0.01 | F29: 0.02 | G29: 0.28 | H29: 0.3 | I29: 0.3 | J29: 0.21 | K29: 0.3 | L29: 0.52 | M29: 0.5 | N29: 0.67 | O29: 0.49 | P29: 0.08 | Q29: 0.33 | R29: 0.13 | S29: 0.4 | T29: 0.6 | U29: 0.62 | V29: 0.58 | W29: 0.25 | X29: 0.29 | Y29: 0.74 | Z29: 0.74 | AA29: 0.68 | AB29: 0.77 | AC29: 1
B30: Hong Kong Equity | C30: -0.04 | D30: 0.05 | E30: -0.06 | F30: 0.03 | G30: 0.23 | H30: 0.26 | I30: 0.24 | J30: 0.18 | K30: 0.24 | L30: 0.48 | M30: 0.44 | N30: 0.59 | O30: 0.49 | P30: -0.02 | Q30: 0.29 | R30: -0.01 | S30: 0.36 | T30: 0.59 | U30: 0.67 | V30: 0.64 | W30: 0.26 | X30: 0.34 | Y30: 0.58 | Z30: 0.6 | AA30: 0.53 | AB30: 0.68 | AC30: 0.59 | AD30: 1
B31: UK Large Cap | C31: 0.04 | D31: 0 | E31: -0.14 | F31: 0.14 | G31: 0.25 | H31: 0.19 | I31: 0.2 | J31: 0.11 | K31: 0.18 | L31: 0.45 | M31: 0.43 | N31: 0.72 | O31: 0.61 | P31: -0.05 | Q31: 0.31 | R31: 0.01 | S31: 0.4 | T31: 0.61 | U31: 0.66 | V31: 0.6 | W31: 0.2 | X31: 0.34 | Y31: 0.82 | Z31: 0.81 | AA31: 0.73 | AB31: 0.91 | AC31: 0.75 | AD31: 0.73 | AE31: 1
B32: EAFE Equity | C32: -0.02 | D32: 0.03 | E32: -0.04 | F32: 0.04 | G32: 0.32 | H32: 0.3 | I32: 0.29 | J32: 0.21 | K32: 0.28 | L32: 0.54 | M32: 0.52 | N32: 0.77 | O32: 0.58 | P32: 0.06 | Q32: 0.41 | R32: 0.11 | S32: 0.49 | T32: 0.7 | U32: 0.75 | V32: 0.66 | W32: 0.26 | X32: 0.33 | Y32: 0.88 | Z32: 0.88 | AA32: 0.8 | AB32: 0.97 | AC32: 0.85 | AD32: 0.73 | AE32: 0.95 | AF32: 1
B33: Chinese Domestic Equity | C33: -0.05 | D33: 0.06 | E33: -0.05 | F33: 0.02 | G33: 0.11 | H33: 0.16 | I33: 0.15 | J33: 0.1 | K33: 0.14 | L33: 0.29 | M33: 0.26 | N33: 0.34 | O33: 0.29 | P33: 0.02 | Q33: 0.15 | R33: 0.02 | S33: 0.18 | T33: 0.34 | U33: 0.36 | V33: 0.4 | W33: 0.11 | X33: 0.18 | Y33: 0.35 | Z33: 0.35 | AA33: 0.32 | AB33: 0.38 | AC33: 0.35 | AD33: 0.59 | AE33: 0.4 | AF33: 0.41 | AG33: 1
B34: Emerging Markets Equity | C34: -0.01 | D34: 0.03 | E34: -0.05 | F34: 0.02 | G34: 0.33 | H34: 0.29 | I34: 0.27 | J34: 0.21 | K34: 0.27 | L34: 0.53 | M34: 0.49 | N34: 0.72 | O34: 0.57 | P34: 0.04 | Q34: 0.39 | R34: 0.08 | S34: 0.47 | T34: 0.7 | U34: 0.8 | V34: 0.7 | W34: 0.24 | X34: 0.37 | Y34: 0.74 | Z34: 0.76 | AA34: 0.68 | AB34: 0.82 | AC34: 0.7 | AD34: 0.84 | AE34: 0.81 | AF34: 0.86 | AG34: 0.56 | AH34: 1
B35: AC Asia ex-Japan Equity | C35: -0.06 | D35: 0.02 | E35: -0.02 | F35: 0.02 | G35: 0.32 | H35: 0.31 | I35: 0.29 | J35: 0.23 | K35: 0.3 | L35: 0.54 | M35: 0.51 | N35: 0.69 | O35: 0.53 | P35: 0.06 | Q35: 0.38 | R35: 0.09 | S35: 0.45 | T35: 0.68 | U35: 0.75 | V35: 0.69 | W35: 0.26 | X35: 0.37 | Y35: 0.71 | Z35: 0.72 | AA35: 0.66 | AB35: 0.78 | AC35: 0.69 | AD35: 0.88 | AE35: 0.77 | AF35: 0.83 | AG35: 0.61 | AH35: 0.98 | AI35: 1
B36: AC World Equity | C36: -0.01 | D36: 0.01 | E36: -0.06 | F36: 0.04 | G36: 0.34 | H36: 0.29 | I36: 0.28 | J36: 0.18 | K36: 0.28 | L36: 0.54 | M36: 0.51 | N36: 0.79 | O36: 0.61 | P36: 0.07 | Q36: 0.37 | R36: 0.14 | S36: 0.45 | T36: 0.69 | U36: 0.71 | V36: 0.65 | W36: 0.25 | X36: 0.34 | Y36: 0.96 | Z36: 0.95 | AA36: 0.87 | AB36: 0.93 | AC36: 0.82 | AD36: 0.7 | AE36: 0.91 | AF36: 0.97 | AG36: 0.42 | AH36: 0.86 | AI36: 0.83 | AJ36: 1
B37: U.S. Equity Value Factor | C37: -0.03 | D37: 0.04 | E37: -0.1 | F37: 0.09 | G37: 0.26 | H37: 0.22 | I37: 0.24 | J37: 0.1 | K37: 0.2 | L37: 0.44 | M37: 0.42 | N37: 0.74 | O37: 0.57 | P37: 0.03 | Q37: 0.25 | R37: 0.12 | S37: 0.33 | T37: 0.58 | U37: 0.6 | V37: 0.54 | W37: 0.2 | X37: 0.27 | Y37: 0.96 | Z37: 0.97 | AA37: 0.93 | AB37: 0.84 | AC37: 0.74 | AD37: 0.57 | AE37: 0.82 | AF37: 0.87 | AG37: 0.33 | AH37: 0.73 | AI37: 0.69 | AJ37: 0.94 | AK37: 1
B38: U.S. Equity Momentum Factor | C38: 0.01 | D38: 0 | E38: -0.07 | F38: 0.02 | G38: 0.35 | H38: 0.27 | I38: 0.26 | J38: 0.11 | K38: 0.27 | L38: 0.5 | M38: 0.48 | N38: 0.76 | O38: 0.61 | P38: 0.08 | Q38: 0.27 | R38: 0.16 | S38: 0.34 | T38: 0.62 | U38: 0.56 | V38: 0.57 | W38: 0.27 | X38: 0.37 | Y38: 0.97 | Z38: 0.96 | AA38: 0.89 | AB38: 0.81 | AC38: 0.72 | AD38: 0.57 | AE38: 0.78 | AF38: 0.85 | AG38: 0.36 | AH38: 0.74 | AI38: 0.71 | AJ38: 0.94 | AK38: 0.91 | AL38: 1
B39: U.S. Equity Quality Factor | C39: -0.02 | D39: 0 | E39: -0.04 | F39: 0.01 | G39: 0.32 | H39: 0.28 | I39: 0.27 | J39: 0.14 | K39: 0.27 | L39: 0.49 | M39: 0.48 | N39: 0.73 | O39: 0.55 | P39: 0.11 | Q39: 0.3 | R39: 0.18 | S39: 0.37 | T39: 0.63 | U39: 0.61 | V39: 0.56 | W39: 0.26 | X39: 0.32 | Y39: 0.99 | Z39: 0.95 | AA39: 0.9 | AB39: 0.84 | AC39: 0.73 | AD39: 0.57 | AE39: 0.81 | AF39: 0.87 | AG39: 0.34 | AH39: 0.72 | AI39: 0.69 | AJ39: 0.95 | AK39: 0.96 | AL39: 0.96 | AM39: 1
B40: U.S. Equity Minimum Volatility Factor | C40: -0.01 | D40: 0.07 | E40: -0.03 | F40: 0.02 | G40: 0.32 | H40: 0.28 | I40: 0.27 | J40: 0.13 | K40: 0.29 | L40: 0.49 | M40: 0.48 | N40: 0.72 | O40: 0.53 | P40: 0.12 | Q40: 0.31 | R40: 0.2 | S40: 0.38 | T40: 0.62 | U40: 0.62 | V40: 0.54 | W40: 0.27 | X40: 0.32 | Y40: 0.93 | Z40: 0.92 | AA40: 0.85 | AB40: 0.8 | AC40: 0.68 | AD40: 0.55 | AE40: 0.78 | AF40: 0.83 | AG40: 0.3 | AH40: 0.69 | AI40: 0.66 | AJ40: 0.9 | AK40: 0.93 | AL40: 0.9 | AM40: 0.95 | AN40: 1
B41: U.S. Equity Dividend Yield Factor | C41: -0.01 | D41: 0.07 | E41: -0.07 | F41: 0.05 | G41: 0.3 | H41: 0.25 | I41: 0.25 | J41: 0.12 | K41: 0.24 | L41: 0.47 | M41: 0.46 | N41: 0.74 | O41: 0.57 | P41: 0.05 | Q41: 0.28 | R41: 0.13 | S41: 0.36 | T41: 0.61 | U41: 0.62 | V41: 0.55 | W41: 0.25 | X41: 0.3 | Y41: 0.93 | Z41: 0.94 | AA41: 0.89 | AB41: 0.82 | AC41: 0.7 | AD41: 0.59 | AE41: 0.83 | AF41: 0.86 | AG41: 0.31 | AH41: 0.73 | AI41: 0.69 | AJ41: 0.91 | AK41: 0.97 | AL41: 0.88 | AM41: 0.93 | AN41: 0.96 | AO41: 1
...

Sheet JPM Cov matrix
C2: US Treasuries, Short/Intermediate | D2: US Treasuries, Long | E2: US Taxable Munis | F2: Global ex-US Government, hedged | G2: US Public Corporates IG AAA | H2: US Public Corporates IG AA | I2: US Public Corporates IG A | J2: US Public Corporates IG BBB | K2: US Public Corporates, HY Intermediate | L2: US Public Corporates, HY Long | M2: Global ex-US Corporates, hedged | N2: Residential Mortgage-Backed Securities | O2: Commercial Mortgage-Backed Securities | P2: Asset-Backed Securities | Q2: Corporate IG Private Placement A | R2: Corporate IG Private Placement BBB | S2: Corporate HY Private (Leveraged Loans) | T2: Residential Mortgage Whole Loans | U2: Commercial Mortgage Whole Loans | V2: Private Equity | W2: Real Estate (via partnerships, equity)
B3: US Treasuries, Short/Intermediate | C3: ='JPM Corr'!Y68*VLOOKUP('JPM Cov matrix'!$B3,'[1]Asset Universe'!$C$3:$O$23,13,0)*VLOOKUP('JPM Cov matrix'!C$2,'[1]Asset Universe'!$C$3:$O$23,13,0) -> 0.0014872008 | D3: ='JPM Corr'!Z68*VLOOKUP('JPM Cov matrix'!$B3,'[1]Asset Universe'!$C$3:$O$23,13,0)*VLOOKUP('JPM Cov matrix'!D$2,'[1]Asset Universe'!$C$3:$O$23,13,0) -> 0.0027267455 | E3: ='JPM Corr'!AA68*VLOOKUP('JPM Cov matrix'!$B3,'[1]Asset Universe'!$C$3:$O$23,13,0)*VLOOKUP('JPM Cov matrix'!E$2,'[1]Asset Universe'!$C$3:$O$23,13,0) -> 0.00083171911 | F3: ='JPM Corr'!AB68*VLOOKUP('JPM Cov matrix'!$B3,'[1]Asset Universe'!$C$3:$O$23,13,0)*VLOOKUP('JPM Cov matrix'!F$2,'[1]Asset Universe'!$C$3:$O$23,13,0) -> 0.0011568286 | G3: ='JPM Corr'!AC68*VLOOKUP('JPM Cov matrix'!$B3,'[1]Asset Universe'!$C$3:$O$23,13,0)*VLOOKUP('JPM Cov matrix'!G$2,'[1]Asset Universe'!$C$3:$O$23,13,0) -> 0.00058985052 | H3: ='JPM Corr'!AD68*VLOOKUP('JPM Cov matrix'!$B3,'[1]Asset Universe'!$C$3:$O$23,13,0)*VLOOKUP('JPM Cov matrix'!H$2,'[1]Asset Universe'!$C$3:$O$23,13,0) -> 0.00067364286 | I3: ='JPM Corr'!AE68*VLOOKUP('JPM Cov matrix'!$B3,'[1]Asset Universe'!$C$3:$O$23,13,0)*VLOOKUP('JPM Cov matrix'!I$2,'[1]Asset Universe'!$C$3:$O$23,13,0) -> 0.00077288679 | J3: ='JPM Corr'!AF68*VLOOKUP('JPM Cov matrix'!$B3,'[1]Asset Universe'!$C$3:$O$23,13,0)*VLOOKUP('JPM Cov matrix'!J$2,'[1]Asset Universe'!$C$3:$O$23,13,0) -> 0.0008841339 | ... W3: ='JPM Corr'!AS68*VLOOKUP('JPM Cov matrix'!$B3,'[1]Asset Universe'!$C$3:$O$23,13,0)*VLOOKUP('JPM Cov matrix'!W$2,'[1]Asset Universe'!$C$3:$O$23,13,0) -> #REF!
B4: US Treasuries, Long | C4: ='JPM Corr'!Y69*VLOOKUP('JPM Cov matrix'!$B4,'[1]Asset Universe'!$C$3:$O$23,13,0)*VLOOKUP('JPM Cov matrix'!C$2,'[1]Asset Universe'!$C$3:$O$23,13,0) -> 0.0027267455 | D4: ='JPM Corr'!Z69*VLOOKUP('JPM Cov matrix'!$B4,'[1]Asset Universe'!$C$3:$O$23,13,0)*VLOOKUP('JPM Cov matrix'!D$2,'[1]Asset Universe'!$C$3:$O$23,13,0) -> 0.0072571053 | E4: ='JPM Corr'!AA69*VLOOKUP('JPM Cov matrix'!$B4,'[1]Asset Universe'!$C$3:$O$23,13,0)*VLOOKUP('JPM Cov matrix'!E$2,'[1]Asset Universe'!$C$3:$O$23,13,0) -> 0.0018019404 | F4: ='JPM Corr'!AB69*VLOOKUP('JPM Cov matrix'!$B4,'[1]Asset Universe'!$C$3:$O$23,13,0)*VLOOKUP('JPM Cov matrix'!F$2,'[1]Asset Universe'!$C$3:$O$23,13,0) -> 0.0026264258 | G4: ='JPM Corr'!AC69*VLOOKUP('JPM Cov matrix'!$B4,'[1]Asset Universe'!$C$3:$O$23,13,0)*VLOOKUP('JPM Cov matrix'!G$2,'[1]Asset Universe'!$C$3:$O$23,13,0) -> 0.0015034423 | H4: ='JPM Corr'!AD69*VLOOKUP('JPM Cov matrix'!$B4,'[1]Asset Universe'!$C$3:$O$23,13,0)*VLOOKUP('JPM Cov matrix'!H$2,'[1]Asset Universe'!$C$3:$O$23,13,0) -> 0.0017170167 | I4: ='JPM Corr'!AE69*VLOOKUP('JPM Cov matrix'!$B4,'[1]Asset Universe'!$C$3:$O$23,13,0)*VLOOKUP('JPM Cov matrix'!I$2,'[1]Asset Universe'!$C$3:$O$23,13,0) -> 0.0019699749 | J4: ='JPM Corr'!AF69*VLOOKUP('JPM Cov matrix'!$B4,'[1]Asset Universe'!$C$3:$O$23,13,0)*VLOOKUP('JPM Cov matrix'!J$2,'[1]Asset Universe'!$C$3:$O$23,13,0) -> 0.0022535274 | ... W4: ='JPM Corr'!AS69*VLOOKUP('JPM Cov matrix'!$B4,'[1]Asset Universe'!$C$3:$O$23,13,0)*VLOOKUP('JPM Cov matrix'!W$2,'[1]Asset Universe'!$C$3:$O$23,13,0) -> #REF!
B5: US Taxable Munis | C5: ='JPM Corr'!Y70*VLOOKUP('JPM Cov matrix'!$B5,'[1]Asset Universe'!$C$3:$O$23,13,0)*VLOOKUP('JPM Cov matrix'!C$2,'[1]Asset Universe'!$C$3:$O$23,13,0) -> 0.00083171911 | D5: ='JPM Corr'!Z70*VLOOKUP('JPM Cov matrix'!$B5,'[1]Asset Universe'!$C$3:$O$23,13,0)*VLOOKUP('JPM Cov matrix'!D$2,'[1]Asset Universe'!$C$3:$O$23,13,0) -> 0.0018019404 | E5: ='JPM Corr'!AA70*VLOOKUP('JPM Cov matrix'!$B5,'[1]Asset Universe'!$C$3:$O$23,13,0)*VLOOKUP('JPM Cov matrix'!E$2,'[1]Asset Universe'!$C$3:$O$23,13,0) -> 0.0017201925 | F5: ='JPM Corr'!AB70*VLOOKUP('JPM Cov matrix'!$B5,'[1]Asset Universe'!$C$3:$O$23,13,0)*VLOOKUP('JPM Cov matrix'!F$2,'[1]Asset Universe'!$C$3:$O$23,13,0) -> 0.0010195118 | G5: ='JPM Corr'!AC70*VLOOKUP('JPM Cov matrix'!$B5,'[1]Asset Universe'!$C$3:$O$23,13,0)*VLOOKUP('JPM Cov matrix'!G$2,'[1]Asset Universe'!$C$3:$O$23,13,0) -> 0.0008417661 | H5: ='JPM Corr'!AD70*VLOOKUP('JPM Cov matrix'!$B5,'[1]Asset Universe'!$C$3:$O$23,13,0)*VLOOKUP('JPM Cov matrix'!H$2,'[1]Asset Universe'!$C$3:$O$23,13,0) -> 0.00096134479 | I5: ='JPM Corr'!AE70*VLOOKUP('JPM Cov matrix'!$B5,'[1]Asset Universe'!$C$3:$O$23,13,0)*VLOOKUP('JPM Cov matrix'!I$2,'[1]Asset Universe'!$C$3:$O$23,13,0) -> 0.0011029742 | J5: ='JPM Corr'!AF70*VLOOKUP('JPM Cov matrix'!$B5,'[1]Asset Universe'!$C$3:$O$23,13,0)*VLOOKUP('JPM Cov matrix'!J$2,'[1]Asset Universe'!$C$3:$O$23,13,0) -> 0.0012617331 | ... W5: ='JPM Corr'!AS70*VLOOKUP('JPM Cov matrix'!$B5,'[1]Asset Universe'!$C$3:$O$23,13,0)*VLOOKUP('JPM Cov matrix'!W$2,'[1]Asset Universe'!$C$3:$O$23,13,0) -> #REF!
B6: Global ex-US Government, hedged | C6: ='JPM Corr'!Y71*VLOOKUP('JPM Cov matrix'!$B6,'[1]Asset Universe'!$C$3:$O$23,13,0)*VLOOKUP('JPM Cov matrix'!C$2,'[1]Asset Universe'!$C$3:$O$23,13,0) -> 0.0011568286 | D6: ='JPM Corr'!Z71*VLOOKUP('JPM Cov matrix'!$B6,'[1]Asset Universe'!$C$3:$O$23,13,0)*VLOOKUP('JPM Cov matrix'!D$2,'[1]Asset Universe'!$C$3:$O$23,13,0) -> 0.0026264258 | E6: ='JPM Corr'!AA71*VLOOKUP('JPM Cov matrix'!$B6,'[1]Asset Universe'!$C$3:$O$23,13,0)*VLOOKUP('JPM Cov matrix'!E$2,'[1]Asset Universe'!$C$3:$O$23,13,0) -> 0.0010195118 | F6: ='JPM Corr'!AB71*VLOOKUP('JPM Cov matrix'!$B6,'[1]Asset Universe'!$C$3:$O$23,13,0)*VLOOKUP('JPM Cov matrix'!F$2,'[1]Asset Universe'!$C$3:$O$23,13,0) -> 0.0017358149 | G6: ='JPM Corr'!AC71*VLOOKUP('JPM Cov matrix'!$B6,'[1]Asset Universe'!$C$3:$O$23,13,0)*VLOOKUP('JPM Cov matrix'!G$2,'[1]Asset Universe'!$C$3:$O$23,13,0) -> 0.00078430591 | H6: ='JPM Corr'!AD71*VLOOKUP('JPM Cov matrix'!$B6,'[1]Asset Universe'!$C$3:$O$23,13,0)*VLOOKUP('JPM Cov matrix'!H$2,'[1]Asset Universe'!$C$3:$O$23,13,0) -> 0.00089572199 | I6: ='JPM Corr'!AE71*VLOOKUP('JPM Cov matrix'!$B6,'[1]Asset Universe'!$C$3:$O$23,13,0)*VLOOKUP('JPM Cov matrix'!I$2,'[1]Asset Universe'!$C$3:$O$23,13,0) -> 0.0010276836 | J6: ='JPM Corr'!AF71*VLOOKUP('JPM Cov matrix'!$B6,'[1]Asset Universe'!$C$3:$O$23,13,0)*VLOOKUP('JPM Cov matrix'!J$2,'[1]Asset Universe'!$C$3:$O$23,13,0) -> 0.0011756054 | ... W6: ='JPM Corr'!AS71*VLOOKUP('JPM Cov matrix'!$B6,'[1]Asset Universe'!$C$3:$O$23,13,0)*VLOOKUP('JPM Cov matrix'!W$2,'[1]Asset Universe'!$C$3:$O$23,13,0) -> #REF!
B7: US Public Corporates IG AAA | C7: ='JPM Corr'!Y72*VLOOKUP('JPM Cov matrix'!$B7,'[1]Asset Universe'!$C$3:$O$23,13,0)*VLOOKUP('JPM Cov matrix'!C$2,'[1]Asset Universe'!$C$3:$O$23,13,0) -> 0.00058985052 | D7: ='JPM Corr'!Z72*VLOOKUP('JPM Cov matrix'!$B7,'[1]Asset Universe'!$C$3:$O$23,13,0)*VLOOKUP('JPM Cov matrix'!D$2,'[1]Asset Universe'!$C$3:$O$23,13,0) -> 0.0015034423 | E7: ='JPM Corr'!AA72*VLOOKUP('JPM Cov matrix'!$B7,'[1]Asset Universe'!$C$3:$O$23,13,0)*VLOOKUP('JPM Cov matrix'!E$2,'[1]Asset Universe'!$C$3:$O$23,13,0) -> 0.0008417661 | F7: ='JPM Corr'!AB72*VLOOKUP('JPM Cov matrix'!$B7,'[1]Asset Universe'!$C$3:$O$23,13,0)*VLOOKUP('JPM Cov matrix'!F$2,'[1]Asset Universe'!$C$3:$O$23,13,0) -> 0.00078430591 | G7: ='JPM Corr'!AC72*VLOOKUP('JPM Cov matrix'!$B7,'[1]Asset Universe'!$C$3:$O$23,13,0)*VLOOKUP('JPM Cov matrix'!G$2,'[1]Asset Universe'!$C$3:$O$23,13,0) -> 0.0008651823 | H7: ='JPM Corr'!AD72*VLOOKUP('JPM Cov matrix'!$B7,'[1]Asset Universe'!$C$3:$O$23,13,0)*VLOOKUP('JPM Cov matrix'!H$2,'[1]Asset Universe'!$C$3:$O$23,13,0) -> 0.00098808742 | I7: ='JPM Corr'!AE72*VLOOKUP('JPM Cov matrix'!$B7,'[1]Asset Universe'!$C$3:$O$23,13,0)*VLOOKUP('JPM Cov matrix'!I$2,'[1]Asset Universe'!$C$3:$O$23,13,0) -> 0.0011336567 | J7: ='JPM Corr'!AF72*VLOOKUP('JPM Cov matrix'!$B7,'[1]Asset Universe'!$C$3:$O$23,13,0)*VLOOKUP('JPM Cov matrix'!J$2,'[1]Asset Universe'!$C$3:$O$23,13,0) -> 0.001296832 | ... W7: ='JPM Corr'!AS72*VLOOKUP('JPM Cov matrix'!$B7,'[1]Asset Universe'!$C$3:$O$23,13,0)*VLOOKUP('JPM Cov matrix'!W$2,'[1]Asset Universe'!$C$3:$O$23,13,0) -> #REF!
B8: US Public Corporates IG AA | C8: ='JPM Corr'!Y73*VLOOKUP('JPM Cov matrix'!$B8,'[1]Asset Universe'!$C$3:$O$23,13,0)*VLOOKUP('JPM Cov matrix'!C$2,'[1]Asset Universe'!$C$3:$O$23,13,0) -> 0.00067364286 | D8: ='JPM Corr'!Z73*VLOOKUP('JPM Cov matrix'!$B8,'[1]Asset Universe'!$C$3:$O$23,13,0)*VLOOKUP('JPM Cov matrix'!D$2,'[1]Asset Universe'!$C$3:$O$23,13,0) -> 0.0017170167 | E8: ='JPM Corr'!AA73*VLOOKUP('JPM Cov matrix'!$B8,'[1]Asset Universe'!$C$3:$O$23,13,0)*VLOOKUP('JPM Cov matrix'!E$2,'[1]Asset Universe'!$C$3:$O$23,13,0) -> 0.00096134479 | F8: ='JPM Corr'!AB73*VLOOKUP('JPM Cov matrix'!$B8,'[1]Asset Universe'!$C$3:$O$23,13,0)*VLOOKUP('JPM Cov matrix'!F$2,'[1]Asset Universe'!$C$3:$O$23,13,0) -> 0.00089572199 | G8: ='JPM Corr'!AC73*VLOOKUP('JPM Cov matrix'!$B8,'[1]Asset Universe'!$C$3:$O$23,13,0)*VLOOKUP('JPM Cov matrix'!G$2,'[1]Asset Universe'!$C$3:$O$23,13,0) -> 0.00098808742 | H8: ='JPM Corr'!AD73*VLOOKUP('JPM Cov matrix'!$B8,'[1]Asset Universe'!$C$3:$O$23,13,0)*VLOOKUP('JPM Cov matrix'!H$2,'[1]Asset Universe'!$C$3:$O$23,13,0) -> 0.0011284521 | I8: ='JPM Corr'!AE73*VLOOKUP('JPM Cov matrix'!$B8,'[1]Asset Universe'!$C$3:$O$23,13,0)*VLOOKUP('JPM Cov matrix'!I$2,'[1]Asset Universe'!$C$3:$O$23,13,0) -> 0.0012947004 | J8: ='JPM Corr'!AF73*VLOOKUP('JPM Cov matrix'!$B8,'[1]Asset Universe'!$C$3:$O$23,13,0)*VLOOKUP('JPM Cov matrix'!J$2,'[1]Asset Universe'!$C$3:$O$23,13,0) -> 0.0014810559 | ... W8: ='JPM Corr'!AS73*VLOOKUP('JPM Cov matrix'!$B8,'[1]Asset Universe'!$C$3:$O$23,13,0)*VLOOKUP('JPM Cov matrix'!W$2,'[1]Asset Universe'!$C$3:$O$23,13,0) -> #REF!
B9: US Public Corporates IG A | C9: ='JPM Corr'!Y74*VLOOKUP('JPM Cov matrix'!$B9,'[1]Asset Universe'!$C$3:$O$23,13,0)*VLOOKUP('JPM Cov matrix'!C$2,'[1]Asset Universe'!$C$3:$O$23,13,0) -> 0.00077288679 | D9: ='JPM Corr'!Z74*VLOOKUP('JPM Cov matrix'!$B9,'[1]Asset Universe'!$C$3:$O$23,13,0)*VLOOKUP('JPM Cov matrix'!D$2,'[1]Asset Universe'!$C$3:$O$23,13,0) -> 0.0019699749 | E9: ='JPM Corr'!AA74*VLOOKUP('JPM Cov matrix'!$B9,'[1]Asset Universe'!$C$3:$O$23,13,0)*VLOOKUP('JPM Cov matrix'!E$2,'[1]Asset Universe'!$C$3:$O$23,13,0) -> 0.0011029742 | F9: ='JPM Corr'!AB74*VLOOKUP('JPM Cov matrix'!$B9,'[1]Asset Universe'!$C$3:$O$23,13,0)*VLOOKUP('JPM Cov matrix'!F$2,'[1]Asset Universe'!$C$3:$O$23,13,0) -> 0.0010276836 | G9: ='JPM Corr'!AC74*VLOOKUP('JPM Cov matrix'!$B9,'[1]Asset Universe'!$C$3:$O$23,13,0)*VLOOKUP('JPM Cov matrix'!G$2,'[1]Asset Universe'!$C$3:$O$23,13,0) -> 0.0011336567 | H9: ='JPM Corr'!AD74*VLOOKUP('JPM Cov matrix'!$B9,'[1]Asset Universe'!$C$3:$O$23,13,0)*VLOOKUP('JPM Cov matrix'!H$2,'[1]Asset Universe'!$C$3:$O$23,13,0) -> 0.0012947004 | I9: ='JPM Corr'!AE74*VLOOKUP('JPM Cov matrix'!$B9,'[1]Asset Universe'!$C$3:$O$23,13,0)*VLOOKUP('JPM Cov matrix'!I$2,'[1]Asset Universe'!$C$3:$O$23,13,0) -> 0.0014854412 | J9: ='JPM Corr'!AF74*VLOOKUP('JPM Cov matrix'!$B9,'[1]Asset Universe'!$C$3:$O$23,13,0)*VLOOKUP('JPM Cov matrix'!J$2,'[1]Asset Universe'!$C$3:$O$23,13,0) -> 0.0016992513 | ... W9: ='JPM Corr'!AS74*VLOOKUP('JPM Cov matrix'!$B9,'[1]Asset Universe'!$C$3:$O$23,13,0)*VLOOKUP('JPM Cov matrix'!W$2,'[1]Asset Universe'!$C$3:$O$23,13,0) -> #REF!
B10: US Public Corporates IG BBB | C10: ='JPM Corr'!Y75*VLOOKUP('JPM Cov matrix'!$B10,'[1]Asset Universe'!$C$3:$O$23,13,0)*VLOOKUP('JPM Cov matrix'!C$2,'[1]Asset Universe'!$C$3:$O$23,13,0) -> 0.0008841339 | D10: ='JPM Corr'!Z75*VLOOKUP('JPM Cov matrix'!$B10,'[1]Asset Universe'!$C$3:$O$23,13,0)*VLOOKUP('JPM Cov matrix'!D$2,'[1]Asset Universe'!$C$3:$O$23,13,0) -> 0.0022535274 | E10: ='JPM Corr'!AA75*VLOOKUP('JPM Cov matrix'!$B10,'[1]Asset Universe'!$C$3:$O$23,13,0)*VLOOKUP('JPM Cov matrix'!E$2,'[1]Asset Universe'!$C$3:$O$23,13,0) -> 0.0012617331 | F10: ='JPM Corr'!AB75*VLOOKUP('JPM Cov matrix'!$B10,'[1]Asset Universe'!$C$3:$O$23,13,0)*VLOOKUP('JPM Cov matrix'!F$2,'[1]Asset Universe'!$C$3:$O$23,13,0) -> 0.0011756054 | G10: ='JPM Corr'!AC75*VLOOKUP('JPM Cov matrix'!$B10,'[1]Asset Universe'!$C$3:$O$23,13,0)*VLOOKUP('JPM Cov matrix'!G$2,'[1]Asset Universe'!$C$3:$O$23,13,0) -> 0.001296832 | H10: ='JPM Corr'!AD75*VLOOKUP('JPM Cov matrix'!$B10,'[1]Asset Universe'!$C$3:$O$23,13,0)*VLOOKUP('JPM Cov matrix'!H$2,'[1]Asset Universe'!$C$3:$O$23,13,0) -> 0.0014810559 | I10: ='JPM Corr'!AE75*VLOOKUP('JPM Cov matrix'!$B10,'[1]Asset Universe'!$C$3:$O$23,13,0)*VLOOKUP('JPM Cov matrix'!I$2,'[1]Asset Universe'!$C$3:$O$23,13,0) -> 0.0016992513 | J10: ='JPM Corr'!AF75*VLOOKUP('JPM Cov matrix'!$B10,'[1]Asset Universe'!$C$3:$O$23,13,0)*VLOOKUP('JPM Cov matrix'!J$2,'[1]Asset Universe'!$C$3:$O$23,13,0) -> 0.0019438367 | ... W10: ='JPM Corr'!AS75*VLOOKUP('JPM Cov matrix'!$B10,'[1]Asset Universe'!$C$3:$O$23,13,0)*VLOOKUP('JPM Cov matrix'!W$2,'[1]Asset Universe'!$C$3:$O$23,13,0) -> #REF!
B11: US Public Corporates, HY Intermediate | C11: ='JPM Corr'!Y76*VLOOKUP('JPM Cov matrix'!$B11,'[1]Asset Universe'!$C$3:$O$23,13,0)*VLOOKUP('JPM Cov matrix'!C$2,'[1]Asset Universe'!$C$3:$O$23,13,0) -> -9.7966695e-05 | D11: ='JPM Corr'!Z76*VLOOKUP('JPM Cov matrix'!$B11,'[1]Asset Universe'!$C$3:$O$23,13,0)*VLOOKUP('JPM Cov matrix'!D$2,'[1]Asset Universe'!$C$3:$O$23,13,0) -> 0 | E11: ='JPM Corr'!AA76*VLOOKUP('JPM Cov matrix'!$B11,'[1]Asset Universe'!$C$3:$O$23,13,0)*VLOOKUP('JPM Cov matrix'!E$2,'[1]Asset Universe'!$C$3:$O$23,13,0) -> 0.0022125927 | F11: ='JPM Corr'!AB76*VLOOKUP('JPM Cov matrix'!$B11,'[1]Asset Universe'!$C$3:$O$23,13,0)*VLOOKUP('JPM Cov matrix'!F$2,'[1]Asset Universe'!$C$3:$O$23,13,0) -> 0.0010054696 | G11: ='JPM Corr'!AC76*VLOOKUP('JPM Cov matrix'!$B11,'[1]Asset Universe'!$C$3:$O$23,13,0)*VLOOKUP('JPM Cov matrix'!G$2,'[1]Asset Universe'!$C$3:$O$23,13,0) -> 0.0024658202 | H11: ='JPM Corr'!AD76*VLOOKUP('JPM Cov matrix'!$B11,'[1]Asset Universe'!$C$3:$O$23,13,0)*VLOOKUP('JPM Cov matrix'!H$2,'[1]Asset Universe'!$C$3:$O$23,13,0) -> 0.002816107 | I11: ='JPM Corr'!AE76*VLOOKUP('JPM Cov matrix'!$B11,'[1]Asset Universe'!$C$3:$O$23,13,0)*VLOOKUP('JPM Cov matrix'!I$2,'[1]Asset Universe'!$C$3:$O$23,13,0) -> 0.0032309878 | J11: ='JPM Corr'!AF76*VLOOKUP('JPM Cov matrix'!$B11,'[1]Asset Universe'!$C$3:$O$23,13,0)*VLOOKUP('JPM Cov matrix'!J$2,'[1]Asset Universe'!$C$3:$O$23,13,0) -> 0.003696047 | ... W11: ='JPM Corr'!AS76*VLOOKUP('JPM Cov matrix'!$B11,'[1]Asset Universe'!$C$3:$O$23,13,0)*VLOOKUP('JPM Cov matrix'!W$2,'[1]Asset Universe'!$C$3:$O$23,13,0) -> #REF!
B12: US Public Corporates, HY Long | C12: ='JPM Corr'!Y77*VLOOKUP('JPM Cov matrix'!$B12,'[1]Asset Universe'!$C$3:$O$23,13,0)*VLOOKUP('JPM Cov matrix'!C$2,'[1]Asset Universe'!$C$3:$O$23,13,0) -> -8.9988516e-05 | D12: ='JPM Corr'!Z77*VLOOKUP('JPM Cov matrix'!$B12,'[1]Asset Universe'!$C$3:$O$23,13,0)*VLOOKUP('JPM Cov matrix'!D$2,'[1]Asset Universe'!$C$3:$O$23,13,0) -> 0 | E12: ='JPM Corr'!AA77*VLOOKUP('JPM Cov matrix'!$B12,'[1]Asset Universe'!$C$3:$O$23,13,0)*VLOOKUP('JPM Cov matrix'!E$2,'[1]Asset Universe'!$C$3:$O$23,13,0) -> 0.0020324043 | F12: ='JPM Corr'!AB77*VLOOKUP('JPM Cov matrix'!$B12,'[1]Asset Universe'!$C$3:$O$23,13,0)*VLOOKUP('JPM Cov matrix'!F$2,'[1]Asset Universe'!$C$3:$O$23,13,0) -> 0.00092358653 | G12: ='JPM Corr'!AC77*VLOOKUP('JPM Cov matrix'!$B12,'[1]Asset Universe'!$C$3:$O$23,13,0)*VLOOKUP('JPM Cov matrix'!G$2,'[1]Asset Universe'!$C$3:$O$23,13,0) -> 0.0022650095 | H12: ='JPM Corr'!AD77*VLOOKUP('JPM Cov matrix'!$B12,'[1]Asset Universe'!$C$3:$O$23,13,0)*VLOOKUP('JPM Cov matrix'!H$2,'[1]Asset Universe'!$C$3:$O$23,13,0) -> 0.0025867698 | I12: ='JPM Corr'!AE77*VLOOKUP('JPM Cov matrix'!$B12,'[1]Asset Universe'!$C$3:$O$23,13,0)*VLOOKUP('JPM Cov matrix'!I$2,'[1]Asset Universe'!$C$3:$O$23,13,0) -> 0.0029678637 | J12: ='JPM Corr'!AF77*VLOOKUP('JPM Cov matrix'!$B12,'[1]Asset Universe'!$C$3:$O$23,13,0)*VLOOKUP('JPM Cov matrix'!J$2,'[1]Asset Universe'!$C$3:$O$23,13,0) -> 0.0033950495 | ... W12: ='JPM Corr'!AS77*VLOOKUP('JPM Cov matrix'!$B12,'[1]Asset Universe'!$C$3:$O$23,13,0)*VLOOKUP('JPM Cov matrix'!W$2,'[1]Asset Universe'!$C$3:$O$23,13,0) -> #REF!
B13: Global ex-US Corporates, hedged | C13: ='JPM Corr'!Y78*VLOOKUP('JPM Cov matrix'!$B13,'[1]Asset Universe'!$C$3:$O$23,13,0)*VLOOKUP('JPM Cov matrix'!C$2,'[1]Asset Universe'!$C$3:$O$23,13,0) -> 0.0007165363 | D13: ='JPM Corr'!Z78*VLOOKUP('JPM Cov matrix'!$B13,'[1]Asset Universe'!$C$3:$O$23,13,0)*VLOOKUP('JPM Cov matrix'!D$2,'[1]Asset Universe'!$C$3:$O$23,13,0) -> 0.0016268006 | E13: ='JPM Corr'!AA78*VLOOKUP('JPM Cov matrix'!$B13,'[1]Asset Universe'!$C$3:$O$23,13,0)*VLOOKUP('JPM Cov matrix'!E$2,'[1]Asset Universe'!$C$3:$O$23,13,0) -> 0.00063148266 | F13: ='JPM Corr'!AB78*VLOOKUP('JPM Cov matrix'!$B13,'[1]Asset Universe'!$C$3:$O$23,13,0)*VLOOKUP('JPM Cov matrix'!F$2,'[1]Asset Universe'!$C$3:$O$23,13,0) -> 0.0010751587 | G13: ='JPM Corr'!AC78*VLOOKUP('JPM Cov matrix'!$B13,'[1]Asset Universe'!$C$3:$O$23,13,0)*VLOOKUP('JPM Cov matrix'!G$2,'[1]Asset Universe'!$C$3:$O$23,13,0) -> 0.00048579683 | H13: ='JPM Corr'!AD78*VLOOKUP('JPM Cov matrix'!$B13,'[1]Asset Universe'!$C$3:$O$23,13,0)*VLOOKUP('JPM Cov matrix'!H$2,'[1]Asset Universe'!$C$3:$O$23,13,0) -> 0.00055480763 | I13: ='JPM Corr'!AE78*VLOOKUP('JPM Cov matrix'!$B13,'[1]Asset Universe'!$C$3:$O$23,13,0)*VLOOKUP('JPM Cov matrix'!I$2,'[1]Asset Universe'!$C$3:$O$23,13,0) -> 0.00063654425 | J13: ='JPM Corr'!AF78*VLOOKUP('JPM Cov matrix'!$B13,'[1]Asset Universe'!$C$3:$O$23,13,0)*VLOOKUP('JPM Cov matrix'!J$2,'[1]Asset Universe'!$C$3:$O$23,13,0) -> 0.0007281666 | ... W13: ='JPM Corr'!AS78*VLOOKUP('JPM Cov matrix'!$B13,'[1]Asset Universe'!$C$3:$O$23,13,0)*VLOOKUP('JPM Cov matrix'!W$2,'[1]Asset Universe'!$C$3:$O$23,13,0) -> #REF!
B14: Residential Mortgage-Backed Securities | C14: ='JPM Corr'!Y79*VLOOKUP('JPM Cov matrix'!$B14,'[1]Asset Universe'!$C$3:$O$23,13,0)*VLOOKUP('JPM Cov matrix'!C$2,'[1]Asset Universe'!$C$3:$O$23,13,0) -> 0.0013865208 | D14: ='JPM Corr'!Z79*VLOOKUP('JPM Cov matrix'!$B14,'[1]Asset Universe'!$C$3:$O$23,13,0)*VLOOKUP('JPM Cov matrix'!D$2,'[1]Asset Universe'!$C$3:$O$23,13,0) -> 0.0029057644 | E14: ='JPM Corr'!AA79*VLOOKUP('JPM Cov matrix'!$B14,'[1]Asset Universe'!$C$3:$O$23,13,0)*VLOOKUP('JPM Cov matrix'!E$2,'[1]Asset Universe'!$C$3:$O$23,13,0) -> 0.0013191209 | F14: ='JPM Corr'!AB79*VLOOKUP('JPM Cov matrix'!$B14,'[1]Asset Universe'!$C$3:$O$23,13,0)*VLOOKUP('JPM Cov matrix'!F$2,'[1]Asset Universe'!$C$3:$O$23,13,0) -> 0.0013443016 | G14: ='JPM Corr'!AC79*VLOOKUP('JPM Cov matrix'!$B14,'[1]Asset Universe'!$C$3:$O$23,13,0)*VLOOKUP('JPM Cov matrix'!G$2,'[1]Asset Universe'!$C$3:$O$23,13,0) -> 0.0010168621 | H14: ='JPM Corr'!AD79*VLOOKUP('JPM Cov matrix'!$B14,'[1]Asset Universe'!$C$3:$O$23,13,0)*VLOOKUP('JPM Cov matrix'!H$2,'[1]Asset Universe'!$C$3:$O$23,13,0) -> 0.0011613144 | I14: ='JPM Corr'!AE79*VLOOKUP('JPM Cov matrix'!$B14,'[1]Asset Universe'!$C$3:$O$23,13,0)*VLOOKUP('JPM Cov matrix'!I$2,'[1]Asset Universe'!$C$3:$O$23,13,0) -> 0.0013324041 | J14: ='JPM Corr'!AF79*VLOOKUP('JPM Cov matrix'!$B14,'[1]Asset Universe'!$C$3:$O$23,13,0)*VLOOKUP('JPM Cov matrix'!J$2,'[1]Asset Universe'!$C$3:$O$23,13,0) -> 0.0015241866 | ... W14: ='JPM Corr'!AS79*VLOOKUP('JPM Cov matrix'!$B14,'[1]Asset Universe'!$C$3:$O$23,13,0)*VLOOKUP('JPM Cov matrix'!W$2,'[1]Asset Universe'!$C$3:$O$23,13,0) -> #REF!
... B23: Real Estate (via partnerships, equity) | C23: ='JPM Corr'!Y88*VLOOKUP('JPM Cov matrix'!$B23,'[1]Asset Universe'!$C$3:$O$23,13,0)*VLOOKUP('JPM Cov matrix'!C$2,'[1]Asset Universe'!$C$3:$O$23,13,0) -> #REF! | D23: ='JPM Corr'!Z88*VLOOKUP('JPM Cov matrix'!$B23,'[1]Asset Universe'!$C$3:$O$23,13,0)*VLOOKUP('JPM Cov matrix'!D$2,'[1]Asset Universe'!$C$3:$O$23,13,0) -> #REF! | E23: ='JPM Corr'!AA88*VLOOKUP('JPM Cov matrix'!$B23,'[1]Asset Universe'!$C$3:$O$23,13,0)*VLOOKUP('JPM Cov matrix'!E$2,'[1]Asset Universe'!$C$3:$O$23,13,0) -> #REF! | F23: ='JPM Corr'!AB88*VLOOKUP('JPM Cov matrix'!$B23,'[1]Asset Universe'!$C$3:$O$23,13,0)*VLOOKUP('JPM Cov matrix'!F$2,'[1]Asset Universe'!$C$3:$O$23,13,0) -> #REF! | G23: ='JPM Corr'!AC88*VLOOKUP('JPM Cov matrix'!$B23,'[1]Asset Universe'!$C$3:$O$23,13,0)*VLOOKUP('JPM Cov matrix'!G$2,'[1]Asset Universe'!$C$3:$O$23,13,0) -> #REF! | H23: ='JPM Corr'!AD88*VLOOKUP('JPM Cov matrix'!$B23,'[1]Asset Universe'!$C$3:$O$23,13,0)*VLOOKUP('JPM Cov matrix'!H$2,'[1]Asset Universe'!$C$3:$O$23,13,0) -> #REF! | I23: ='JPM Corr'!AE88*VLOOKUP('JPM Cov matrix'!$B23,'[1]Asset Universe'!$C$3:$O$23,13,0)*VLOOKUP('JPM Cov matrix'!I$2,'[1]Asset Universe'!$C$3:$O$23,13,0) -> #REF! | J23: ='JPM Corr'!AF88*VLOOKUP('JPM Cov matrix'!$B23,'[1]Asset Universe'!$C$3:$O$23,13,0)*VLOOKUP('JPM Cov matrix'!J$2,'[1]Asset Universe'!$C$3:$O$23,13,0) -> #REF! | ... W23: ='JPM Corr'!AS88*VLOOKUP('JPM Cov matrix'!$B23,'[1]Asset Universe'!$C$3:$O$23,13,0)*VLOOKUP('JPM Cov matrix'!W$2,'[1]Asset Universe'!$C$3:$O$23,13,0) -> #REF!

Sheet Levels
A1: Date | B1: US Treasuries, Short/Intermediate | C1: US Treasuries, Long | D1: US Taxable Munis | E1: Global ex-US Government, hedged | F1: US Public Corporates IG AAA | G1: US Public Corporates IG AA | H1: US Public Corporates IG A | I1: US Public Corporates IG BBB | J1: US Public Corporates, HY Intermediate | K1: US Public Corporates, HY Long | L1: Global ex-US Corporates, hedged | M1: Residential Mortgage-Backed Securities | N1: Commercial Mortgage-Backed Securities | O1: Asset-Backed Securities | P1: Corporate IG Private Placement A | Q1: Corporate IG Private Placement BBB | R1: Corporate HY Private (Leveraged Loans) | S1: Residential Mortgage Whole Loans | T1: Commercial Mortgage Whole Loans | U1: Private Equity | V1: Real Estate (via partnerships, equity) | X1: 3M T-Bill yield | Y1: Cash return
A2: 39506 | B2: 1464.46 | C2: 1987.37 | D2: 729.4767 | E2: 153.0907 | F2: 253.03 | G2: 269.54 | H2: 261.96 | I2: 271.85 | J2: 797.6656 | K2: 1424.07 | L2: #N/A | M2: 1455.9 | N2: 167.51 | O2: 249.23 | P2: 258.43 | Q2: 270.84167 | R2: #N/A | S2: #N/A | T2: 95.8464 | U2: 687.97 | V2: 1441.48 | X2: 0.01843 | Y2: =(1+X2)^(1/12)-1 -> 0.0015230108
A3: 39538 | B3: 1473.94 | C3: 2004.63 | D3: 750.3328 | E3: 153.1783 | F3: 254.88 | G3: 267.4 | H3: 258.25 | I3: 268.82 | J3: 795.9803 | K3: 1401.88 | L3: #N/A | M3: 1464.08 | N3: 171.95 | O3: 247.08 | P3: 259.205 | Q3: 271.19333 | R3: #N/A | S3: #N/A | T3: 97.5098 | U3: 716.18 | V3: 1552.82 | X3: 0.01321 | Y3: =(1+X3)^(1/12)-1 -> 0.001094224
A4: 39568 | B4: 1449.39 | C4: 1966.16 | D4: 759.1068 | E4: 152.1938 | F4: 253.65 | G4: 267.72 | H4: 260.61 | I4: 272.34 | J4: 830.0139 | K4: 1466.91 | L4: #N/A | M4: 1465.48 | N4: 174.8 | O4: 244.86 | P4: 259.85667 | Q4: 271.485 | R4: #N/A | S4: #N/A | T4: 99.7839 | U4: 748.28 | V4: 1511.79 | X4: 0.01382 | Y4: =(1+X4)^(1/12)-1 -> 0.0011444356
A5: 39599 | B5: 1435.56 | C5: 1927.01 | D5: 763.7047 | E5: 150.516 | F5: 251.91 | G5: 265.05 | H5: 257.7 | I5: 270.65 | J5: 834.2706 | K5: 1450.54 | L5: #N/A | M5: 1457.71 | N5: 176.01 | O5: 246.28 | P5: 259.725 | Q5: 271.35833 | R5: #N/A | S5: #N/A | T5: 100.8726 | U5: 689.66 | V5: 1308.35 | X5: 0.01884 | Y5: =(1+X5)^(1/12)-1 -> 0.001556604
A6: 39629 | B6: 1443.44 | C6: 1960.05 | D6: 755.0784 | E6: 149.5365 | F6: 252.11 | G6: 262.93 | H6: 255.95 | I6: 269.17 | J6: 811.4952 | K6: 1401.86 | L6: #N/A | M6: 1456.88 | N6: 172.26 | O6: 245.1 | P6: 259.3 | Q6: 270.93 | R6: #N/A | S6: #N/A | T6: 98.601 | U6: 714.52 | V6: 1328.89 | X6: 0.01736 | Y6: =(1+X6)^(1/12)-1 -> 0.0014352821
A7: 39660 | B7: 1451.35 | C7: 1958.62 | D7: 757.9511 | E7: 151.8426 | F7: 252.34 | G7: 261.46 | H7: 253.68 | I7: 267.42 | J7: 802.2445 | K7: 1358.47 | L7: #N/A | M7: 1454.85 | N7: 171.32 | O7: 245.16 | P7: 258.025 | Q7: 270.04167 | R7: #N/A | S7: #N/A | T7: 97.7168 | U7: 739.5 | V7: 1373.7 | X7: 0.01665 | Y7: =(1+X7)^(1/12)-1 -> 0.0013770229
A8: 39691 | B8: 1465.04 | C8: 2007.25 | D8: 766.8225 | E8: 153.3891 | F8: 254.91 | G8: 262.94 | H8: 255.39 | I8: 269.5 | J8: 804.6115 | K8: 1370.51 | L8: #N/A | M8: 1473.05 | N8: 169.92 | O8: 242.28 | P8: 256.93 | Q8: 269.65 | R8: #N/A | S8: #N/A | T8: 96.5219 | U8: 679.58 | V8: 1301.36 | X8: 0.01715 | Y8: =(1+X8)^(1/12)-1 -> 0.0014180544
A9: 39721 | B9: 1474.82 | C9: 2015.24 | D9: 730.8595 | E9: 153.8655 | F9: 255.35 | G9: 249.87 | H9: 230.3 | I9: 256.12 | J9: 742.4087 | K9: 1228.05 | L9: #N/A | M9: 1484.13 | N9: 162.21 | O9: 235.97 | P9: 252.27167 | Q9: 267.53333 | R9: #N/A | S9: #N/A | T9: 92.4345 | U9: 537.52 | V9: 1036.07 | X9: 0.0091 | Y9: =(1+X9)^(1/12)-1 -> 0.00075518872
A10: 39752 | B10: 1484.67 | C10: 1949.44 | D10: 723.3974 | E10: 154.9711 | F10: 252.07 | G10: 243.97 | H10: 217.75 | I10: 228 | J10: 625.1731 | K10: 1018.6 | L10: #N/A | M10: 1465.48 | N10: 146.45 | O10: 222.03 | P10: 245.12833 | Q10: 260.14333 | R10: #N/A | S10: #N/A | T10: 83.1621 | U10: 473.14 | V10: 879.88 | X10: 0.00438 | Y10: =(1+X10)^(1/12)-1 -> 0.00036426931
A11: 39782 | B11: 1539.56 | C11: 2189.27 | D11: 725.6991 | E11: 159.1998 | F11: 260.06 | G11: 252.01 | H11: 227.55 | I11: 234.27 | J11: 566.9635 | K11: 923.52 | L11: #N/A | M11: 1523.05 | N11: 119.91 | O11: 221.19 | P11: 240.10333 | Q11: 254.08 | R11: #N/A | S11: #N/A | T11: 67.7804 | U11: 499.45 | V11: 875.2 | X11: 0.00046 | Y11: =(1+X11)^(1/12)-1 -> 3.8325254e-05
A12: 39813 | B12: 1569.88 | C12: 2391.27 | D12: 736.2752 | E12: 163.5356 | F12: 268.07 | G12: 266.95 | H12: 244.99 | I12: 247.54 | J12: 610.2872 | K12: 998.42 | L12: #N/A | M12: 1548.48 | N12: 140.27 | O12: 219.89 | P12: 238.27667 | Q12: 250.475 | R12: #N/A | S12: #N/A | T12: 78.4515 | U12: 443.53 | V12: 825.12 | X12: 0.00081 | Y12: =(1+X12)^(1/12)-1 -> 6.7474954e-05
A13: 39844 | B13: 1546.81 | C13: 2184.43 | D13: 763.2312 | E13: 161.4476 | F13: 264.9 | G13: 261.59 | H13: 244.74 | I13: 252.91 | J13: 647.4725 | K13: 1048.08 | L13: #N/A | M13: 1551.41 | N13: 135.11 | O13: 234.17 | P13: 236.78667 | Q13: 248.05667 | R13: #N/A | S13: #N/A | T13: 75.9917 | U13: 389.02 | V13: 691.63 | X13: 0.00231 | Y13: =(1+X13)^(1/12)-1 -> 0.00019229649
... A67: 41486 | B67: 1745.97 | C67: 2772.08 | D67: 970.4765 | E67: 191.1302 | F67: 314.59 | G67: 346.18 | H67: 357.14 | I67: 412.85 | J67: 1358.33 | K67: 3005.26 | L67: #N/A | M67: 1843.45 | N67: 250.21 | O67: 313.4 | P67: 363.57833 | Q67: 422.16833 | R67: #N/A | S67: #N/A | T67: 142.1927 | U67: 1010.9 | V67: 1530.45 | X67: 0.00038 | Y67: =(1+X67)^(1/12)-1 -> 3.1661153e-05
A68: 41517 | B68: 1738.07 | C68: 2751.33 | D68: 956.6339 | E68: 189.9953 | F68: 313.33 | G68: 343.92 | H68: 354.55 | I68: 408.81 | J68: 1350.95 | K68: 2951.66 | L68: 99.3793 | M68: 1838.18 | N68: 249.19 | O68: 312.75 | P68: 361.545 | Q68: 419.4 | R68: #N/A | S68: #N/A | T68: 141.5362 | U68: 1073.79 | V68: 1571.49 | X68: 0.00023 | Y68: =(1+X68)^(1/12)-1 -> 1.9164646e-05
A69: 41547 | B69: 1750.94 | C69: 2761.52 | D69: 977.2203 | E69: 191.4491 | F69: 316.42 | G69: 346.6 | H69: 357.24 | I69: 412.75 | J69: 1364.492 | K69: 2975.51 | L69: 100.3338 | M69: 1864.06 | N69: 251.47 | O69: 314.5 | P69: 360.03333 | Q69: 417.18833 | R69: #N/A | S69: #N/A | T69: 142.9182 | U69: 1100.15 | V69: 1606.34 | X69: 8e-05 | Y69: =(1+X69)^(1/12)-1 -> 6.6664222e-06
A70: 41578 | B70: 1757.55 | C70: 2798.28 | D70: 984.9366 | E70: 192.9277 | F70: 318.21 | G70: 349.57 | H70: 362.1 | I70: 420.18 | J70: 1397.8825 | K70: 3083.05 | L70: 101.5613 | M70: 1876.76 | N70: 253.27 | O70: 315.52 | P70: 358.23833 | Q70: 414.69333 | R70: #N/A | S70: #N/A | T70: 144.0635 | U70: 1142.89 | V70: 1545.41 | X70: 0.00038 | Y70: =(1+X70)^(1/12)-1 -> 3.1661153e-05
A71: 41608 | B71: 1756.5 | C71: 2729.28 | D71: 982.9057 | E71: 192.4111 | F71: 316.89 | G71: 349.43 | H71: 361.46 | I71: 418.33 | J71: 1405.243 | K71: 3087.18 | L71: 101.436 | M71: 1865.08 | N71: 253.54 | O71: 316.2 | P71: 357.80167 | Q71: 413.745 | R71: #N/A | S71: #N/A | T71: 144.1957 | U71: 1163.64 | V71: 1522.65 | X71: 0.00058 | Y71: =(1+X71)^(1/12)-1 -> 4.8320489e-05
A72: 41639 | B72: 1742.78 | C72: 2676.43 | D72: 980.3961 | E72: 191.5678 | F72: 314.68 | G72: 347.37 | H72: 360.44 | I72: 418.3 | J72: 1412.611 | K72: 3112.84 | L72: 101.0293 | M72: 1856.28 | N72: 252.81 | O72: 315.5 | P72: 358.82167 | Q72: 415.20333 | R72: #N/A | S72: #N/A | T72: 143.7506 | U72: 1130.88 | V72: 1549.65 | X72: 0.00068 | Y72: =(1+X72)^(1/12)-1 -> 5.6649013e-05
A73: 41670 | B73: 1757.63 | C73: 2824.42 | D73: 999.4992 | E73: 193.9558 | F73: 319.09 | G73: 352.63 | H73: 366.83 | I73: 425.26 | J73: 1421.905 | K73: 3159.45 | L73: 102.1837 | M73: 1885.3 | N73: 254.88 | O73: 316.9 | P73: 360.43667 | Q73: 417.27167 | R73: #N/A | S73: #N/A | T73: 145.0185 | U73: 1183.03 | V73: 1571.39 | X73: 0.00023 | Y73: =(1+X73)^(1/12)-1 -> 1.9164646e-05
A74: 41698 | B74: 1761.18 | C74: 2847.77 | D74: 1011.2186 | E74: 194.9646 | F74: 320.08 | G74: 354.76 | H74: 370.27 | I74: 431.56 | J74: 1449.326 | K74: 3280.4 | L74: 102.9713 | M74: 1891.79 | N74: 256.34 | O74: 317.64 | P74: 363.05667 | Q74: 421.06333 | R74: #N/A | S74: #N/A | T74: 145.9091 | U74: 1173.04 | V74: 1570.13 | X74: 0.00048 | Y74: =(1+X74)^(1/12)-1 -> 3.9991203e-05
A75: 41729 | B75: 1754.03 | C75: 2866.52 | D75: 1012.9155 | E75: 195.6249 | F75: 319.15 | G75: 354.52 | H75: 370.08 | I75: 433.3 | J75: 1452.547 | K75: 3296.88 | L75: 103.1676 | M75: 1885.71 | N75: 256.07 | O75: 317.19 | P75: 365.19667 | Q75: 424.48833 | R75: #N/A | S75: #N/A | T75: 145.7718 | U75: 1126.86 | V75: 1604.21 | X75: 0.00033 | Y75: =(1+X75)^(1/12)-1 -> 2.7495842e-05
A76: 41759 | B76: 1760.41 | C76: 2923.77 | D76: 1025.0878 | E76: 196.7947 | F76: 321.39 | G76: 357.36 | H76: 374 | I76: 439.88 | J76: 1460.518 | K76: 3369.58 | L76: 104.0176 | M76: 1903.14 | N76: 257.29 | O76: 318.28 | P76: 367.18 | Q76: 427.77167 | R76: #N/A | S76: #N/A | T76: 146.5821 | U76: 1134.5 | V76: 1675.93 | X76: 0.00028 | Y76: =(1+X76)^(1/12)-1 -> 2.3330339e-05
A77: 41790 | B77: 1772.49 | C77: 3007.86 | D77: 1038.2916 | E77: 198.7316 | F77: 324.69 | G77: 361.25 | H77: 378.92 | I77: 447.18 | J77: 1472.461 | K77: 3462.94 | L77: 105.2964 | M77: 1926.04 | N77: 258.96 | O77: 319.52 | P77: 370.09 | Q77: 432.58 | R77: #N/A | S77: #N/A | T77: 147.6306 | U77: 1192.96 | V77: 1683.84 | X77: 0.00033 | Y77: =(1+X77)^(1/12)-1 -> 2.7495842e-05
A78: 41820 | B78: 1770.15 | C78: 3001.26 | D78: 1039.1906 | E78: 199.8762 | F78: 324.81 | G78: 361.09 | H78: 379.12 | I78: 448 | J78: 1484.054 | K78: 3519.24 | L78: 105.6292 | M78: 1931.09 | N78: 259.43 | O78: 319.63 | P78: 373.20333 | Q78: 437.53 | R78: #N/A | S78: #N/A | T78: 147.9181 | U78: 1120.07 | V78: 1726.16 | X78: 0.00023 | Y78: =(1+X78)^(1/12)-1 -> 1.9164646e-05
A79: 41851 | B79: 1765.53 | C79: 3017.8 | D79: 1041.0229 | E79: 200.9533 | F79: 323.71 | G79: 360.83 | H79: 378.91 | I79: 448 | J79: 1463.882 | K79: 3488.3 | L79: 105.8381 | M79: 1919.76 | N79: 258.81 | O79: 319.12 | P79: 375.21667 | Q79: 441.32 | R79: #N/A | S79: #N/A | T79: 147.5563 | U79: 1174.35 | V79: 1776.34 | X79: 0.00023 | Y79: =(1+X79)^(1/12)-1 -> 1.9164646e-05
... A120: 43100 | B120: 1848.73 | C120: 3636.65 | D120: 1167.4901 | E120: 224.7677 | F120: 347.96 | G120: 400.01 | H120: 432.27 | I120: 510.58 | J120: 1713.2566 | K120: 5011.55 | L120: 119.3571 | M120: 2082.61 | N120: 283.12 | O120: 337.19 | P120: 428.51667 | Q120: 505.46833 | R120: #N/A | S120: #N/A | T120: 162.0131 | U120: 1574.98 | V120: 1970.72 | X120: 0.01382 | Y120: =(1+X120)^(1/12)-1 -> 0.0011444356
A121: 43131 | B121: 1830.69 | C121: 3519.21 | D121: 1153.7452 | E121: 223.5054 | F121: 343.62 | G121: 396.24 | H121: 427.03 | I121: 507.28 | J121: 1722.2602 | K121: 5093.59 | L121: 118.7181 | M121: 2058.2 | N121: 280.05 | O121: 336.22 | P121: 428.865 | Q121: 506.55167 | R121: #N/A | S121: 98.8748 | T121: 160.4061 | U121: 1512.45 | V121: 1874.5 | X121: 0.01459 | Y121: =(1+X121)^(1/12)-1 -> 0.0012077779
A122: 43159 | B122: 1825.2 | C122: 3413.53 | D122: 1150.2979 | E122: 224.125 | F122: 341.22 | G122: 392.6 | H122: 420.15 | I122: 498.59 | J122: 1709.6541 | K122: 4962.42 | L122: 118.201 | M122: 2044.7 | N122: 278.32 | O122: 335.3 | P122: 427.40833 | Q122: 505.55333 | R122: #N/A | S122: 98.164 | T122: 159.4145 | U122: 1529.43 | V122: 1894.52 | X122: 0.01656 | Y122: =(1+X122)^(1/12)-1 -> 0.0013696353
A123: 43190 | B123: 1834.91 | C123: 3516.87 | D123: 1154.5437 | E123: 227.0461 | F123: 343.89 | G123: 394.6 | H123: 421.49 | I123: 499.59 | J123: 1700.2905 | K123: 4885.41 | L123: 118.574 | M123: 2057.76 | N123: 279.4 | O123: 335.89 | P123: 426.425 | Q123: 504.75167 | R123: #N/A | S123: 98.7205 | T123: 160.0725 | U123: 1541.88 | V123: 1961.42 | X123: 0.01706 | Y123: =(1+X123)^(1/12)-1 -> 0.0014106701
A124: 43220 | B124: 1824.27 | C124: 3448.5 | D124: 1150.4233 | E124: 226.3719 | F124: 341.58 | G124: 391.99 | H124: 417.58 | I124: 494.56 | J124: 1711.0301 | K124: 4933.28 | L124: 118.3066 | M124: 2047.42 | N124: 277.46 | O124: 335.76 | P124: 424.52 | Q124: 502.78 | R124: #N/A | S124: 98.2134 | T124: 159.0318 | U124: 1633.61 | V124: 2056.86 | X124: 0.01802 | Y124: =(1+X124)^(1/12)-1 -> 0.0014894051
A125: 43251 | B125: 1836.19 | C125: 3521.46 | D125: 1163.597 | E125: 226.6213 | F125: 344.32 | G125: 394.63 | H125: 420.05 | I125: 496.3 | J125: 1711.5901 | K125: 4880.63 | L125: 118.5395 | M125: 2061.73 | N125: 279.69 | O125: 337.13 | P125: 423.095 | Q125: 501.15 | R125: #N/A | S125: 98.8726 | T125: 160.3079 | U125: 1643.07 | V125: 2076.7 | X125: 0.019 | Y125: =(1+X125)^(1/12)-1 -> 0.0015697102
A126: 43281 | B126: 1835.98 | C126: 3527.72 | D126: 1164.5902 | E126: 227.552 | F126: 344.41 | G126: 393.78 | H126: 417.89 | I126: 493.5 | J126: 1718.9755 | K126: 4874.27 | L126: 118.581 | M126: 2062.73 | N126: 279.22 | O126: 337.28 | P126: 420.69833 | Q126: 498.30333 | R126: #N/A | S126: 98.9131 | T126: 160.1125 | U126: 1670.8 | V126: 2087.23 | X126: 0.01917 | Y126: =(1+X126)^(1/12)-1 -> 0.0015836335
A127: 43312 | B127: 1832.27 | C127: 3475.81 | D127: 1167.4161 | E127: 227.5028 | F127: 343.5 | G127: 394.3 | H127: 420.64 | I127: 498.59 | J127: 1737.5411 | K127: 4937.74 | L127: 119.1219 | M127: 2060.55 | N127: 279.15 | O127: 337.61 | P127: 419.63333 | Q127: 496.855 | R127: #N/A | S127: 98.7807 | T127: 160.1379 | U127: 1740.75 | V127: 2120.11 | X127: 0.02023 | Y127: =(1+X127)^(1/12)-1 -> 0.0016704012
A128: 43343 | B128: 1843.26 | C128: 3530.61 | D128: 1170.4142 | E128: 228.0647 | F128: 345.88 | G128: 396.96 | H128: 423.02 | I128: 500.73 | J128: 1750.0675 | K128: 4989.12 | L128: 119.6276 | M128: 2073.03 | N128: 281.89 | O128: 339.08 | P128: 420.11167 | Q128: 497.21167 | R128: #N/A | S128: 99.4183 | T128: 161.7281 | U128: 1696.57 | V128: 2071.78 | X128: 0.02098 | Y128: =(1+X128)^(1/12)-1 -> 0.0017317436
A129: 43373 | B129: 1833.71 | C129: 3426.03 | D129: 1162.8369 | E129: 227.4289 | F129: 343.22 | G129: 395.12 | H129: 420.74 | I129: 500.17 | J129: 1759.6985 | K129: 5022.93 | L129: 119.3557 | M129: 2060.3 | N129: 280.5 | O129: 338.95 | P129: 419.98667 | Q129: 497.30833 | R129: #N/A | S129: 98.771 | T129: 160.9909 | U129: 1511.41 | V129: 2042.28 | X129: 0.022 | Y129: =(1+X129)^(1/12)-1 -> 0.001815103
A130: 43404 | B130: 1834.38 | C130: 3321.66 | D130: 1155.6761 | E130: 227.8778 | F130: 341.41 | G130: 391.98 | H130: 415.19 | I130: 491.38 | J130: 1732.485 | K130: 4892.23 | L130: 118.9971 | M130: 2047.31 | N130: 278.94 | O130: 339.19 | P130: 419.58833 | Q130: 496.77833 | R130: #N/A | S130: 98.129 | T130: 160.1682 | U130: 1533.27 | V130: 2114.61 | X130: 0.02328 | Y130: =(1+X130)^(1/12)-1 -> 0.0019196029
A131: 43434 | B131: 1847.08 | C131: 3384.52 | D131: 1168.4675 | E131: 229.3293 | F131: 344.39 | G131: 393.59 | H131: 415.29 | I131: 489.45 | J131: 1719.3379 | K131: 4758.08 | L131: 118.9143 | M131: 2065.76 | N131: 280.79 | O131: 340.48 | P131: 418.795 | Q131: 495.63667 | R131: #N/A | S131: 99.0859 | T131: 161.1877 | U131: 1348.56 | V131: 1970.33 | X131: 0.02345 | Y131: =(1+X131)^(1/12)-1 -> 0.0019334728
A132: 43465 | B132: 1874.81 | C132: 3569.7 | D132: 1182.4579 | E132: 232.6335 | F132: 351.18 | G132: 400.37 | H132: 422.21 | I132: 495.69 | J132: 1682.9589 | K132: 4631.58 | L132: 120.1389 | M132: 2103.22 | N132: 285.33 | O132: 343.17 | P132: 419.515 | Q132: 496.00167 | R132: #N/A | S132: 100.9055 | T132: 163.6561 | U132: 1499.42 | V132: 2173.67 | X132: 0.02361 | Y132: =(1+X132)^(1/12)-1 -> 0.0019465249
A133: 43496 | B133: 1882.86 | C133: 3593.66 | D133: 1191.396 | E133: 234.7405 | F133: 353.35 | G133: 405.51 | H133: 431.18 | I133: 508.58 | J133: 1757.863 | K133: 4907.85 | L133: 121.934 | M133: 2119.9 | N133: 288.32 | O133: 344.78 | P133: 421.27167 | Q133: 497.66667 | R133: 102.3059 | S133: 101.7171 | T133: 165.37 | U133: 1575.55 | V133: 2183.66 | X133: 0.0239 | Y133: =(1+X133)^(1/12)-1 -> 0.0019701771
...

Sheet Returns
A1: Date | B1: US Treasuries, Short/Intermediate | C1: US Treasuries, Long | D1: US Taxable Munis | E1: Global ex-US Government, hedged | F1: US Public Corporates IG AAA | G1: US Public Corporates IG AA | H1: US Public Corporates IG A | I1: US Public Corporates IG BBB | J1: US Public Corporates, HY Intermediate | K1: US Public Corporates, HY Long | L1: Global ex-US Corporates, hedged | M1: Residential Mortgage-Backed Securities | N1: Commercial Mortgage-Backed Securities | O1: Asset-Backed Securities | P1: Corporate IG Private Placement A | Q1: Corporate IG Private Placement BBB | R1: Corporate HY Private (Leveraged Loans) | S1: Residential Mortgage Whole Loans | T1: Commercial Mortgage Whole Loans | U1: Private Equity | V1: Real Estate (via partnerships, equity)
A2: 39538 | B2: =Levels!B3/Levels!B2-1-Levels!$Y2 -> 0.0049503651 | C2: =Levels!C3/Levels!C2-1-Levels!$Y2 -> 0.007161834 | D2: =Levels!D3/Levels!D2-1-Levels!$Y2 -> 0.027067484 | E2: =Levels!E3/Levels!E2-1-Levels!$Y2 -> -0.00095080095 | F2: =Levels!F3/Levels!F2-1-Levels!$Y2 -> 0.0057883752 | G2: =Levels!G3/Levels!G2-1-Levels!$Y2 -> -0.0094624632 | H2: =Levels!H3/Levels!H2-1-Levels!$Y2 -> -0.015685478 | I2: =Levels!I3/Levels!I2-1-Levels!$Y2 -> -0.012668863 | ... T2: =Levels!T3/Levels!T2-1-Levels!$Y2 -> 0.01583184 | U2: =(Levels!U3/Levels!U2-1-Levels!$Y2)*$Y$2 -> 0.047378021 | V2: =(Levels!V3/Levels!V2-1-Levels!$Y2) -> 0.075717048 | X2: Leverage for PE | Y2: 1.2
A3: 39568 | B3: =Levels!B4/Levels!B3-1-Levels!$Y3 -> -0.017750262 | C3: =Levels!C4/Levels!C3-1-Levels!$Y3 -> -0.020284798 | D3: =Levels!D4/Levels!D3-1-Levels!$Y3 -> 0.010599254 | E3: =Levels!E4/Levels!E3-1-Levels!$Y3 -> -0.0075213745 | F3: =Levels!F4/Levels!F3-1-Levels!$Y3 -> -0.0059200243 | G3: =Levels!G4/Levels!G3-1-Levels!$Y3 -> 0.00010248509 | H3: =Levels!H4/Levels!H3-1-Levels!$Y3 -> 0.0080442078 | I3: =Levels!I4/Levels!I3-1-Levels!$Y3 -> 0.01200004 | ... T3: =Levels!T4/Levels!T3-1-Levels!$Y3 -> 0.022227534 | U3: =(Levels!U4/Levels!U3-1-Levels!$Y3)*$Y$2 -> 0.052472292 | V3: =(Levels!V4/Levels!V3-1-Levels!$Y3) -> -0.027517119
A4: 39599 | B4: =Levels!B5/Levels!B4-1-Levels!$Y4 -> -0.010686381 | C4: =Levels!C5/Levels!C4-1-Levels!$Y4 -> -0.021056345 | D4: =Levels!D5/Levels!D4-1-Levels!$Y4 -> 0.0049125514 | E4: =Levels!E5/Levels!E4-1-Levels!$Y4 -> -0.012168538 | F4: =Levels!F5/Levels!F4-1-Levels!$Y4 -> -0.0080042818 | G4: =Levels!G5/Levels!G4-1-Levels!$Y4 -> -0.011117542 | H4: =Levels!H5/Levels!H4-1-Levels!$Y4 -> -0.012310546 | I4: =Levels!I5/Levels!I4-1-Levels!$Y4 -> -0.007349914 | ... T4: =Levels!T5/Levels!T4-1-Levels!$Y4 -> 0.0097661422 | U4: =(Levels!U5/Levels!U4-1-Levels!$Y4)*$Y$2 -> -0.095380913 | V4: =(Levels!V5/Levels!V4-1-Levels!$Y4) -> -0.13571339
A5: 39629 | B5: =Levels!B6/Levels!B5-1-Levels!$Y5 -> 0.0039325431 | C5: =Levels!C6/Levels!C5-1-Levels!$Y5 -> 0.01558913 | D5: =Levels!D6/Levels!D5-1-Levels!$Y5 -> -0.012851938 | E5: =Levels!E6/Levels!E5-1-Levels!$Y5 -> -0.0080642178 | F5: =Levels!F6/Levels!F5-1-Levels!$Y5 -> -0.00076266968 | G5: =Levels!G6/Levels!G5-1-Levels!$Y5 -> -0.0095550949 | H5: =Levels!H6/Levels!H5-1-Levels!$Y5 -> -0.0083474461 | I5: =Levels!I6/Levels!I5-1-Levels!$Y5 -> -0.007024921 | ... T5: =Levels!T6/Levels!T5-1-Levels!$Y5 -> -0.024076099 | U5: =(Levels!U6/Levels!U5-1-Levels!$Y5)*$Y$2 -> 0.041388172 | V5: =(Levels!V6/Levels!V5-1-Levels!$Y5) -> 0.014142559
A6: 39660 | B6: =Levels!B7/Levels!B6-1-Levels!$Y6 -> 0.0040446824 | C6: =Levels!C7/Levels!C6-1-Levels!$Y6 -> -0.0021648553 | D6: =Levels!D7/Levels!D6-1-Levels!$Y6 -> 0.0023692235 | E6: =Levels!E7/Levels!E6-1-Levels!$Y6 -> 0.013986371 | F6: =Levels!F7/Levels!F6-1-Levels!$Y6 -> -0.00052298191 | G6: =Levels!G7/Levels!G6-1-Levels!$Y6 -> -0.0070261238 | H6: =Levels!H7/Levels!H6-1-Levels!$Y6 -> -0.010304202 | I6: =Levels!I7/Levels!I6-1-Levels!$Y6 -> -0.0079367496 | ... T6: =Levels!T7/Levels!T6-1-Levels!$Y6 -> -0.010402737 | U6: =(Levels!U7/Levels!U6-1-Levels!$Y6)*$Y$2 -> 0.040230301 | V6: =(Levels!V7/Levels!V6-1-Levels!$Y6) -> 0.032284589
